Workbook
Name Array: [1]TitlePage!D32:H33
Name Data: [1]TitlePage!F16:F21
Name h: #REF!
Name LocalData: [1]TitlePage!G16:G22
Name Population: #REF!

Sheet 1.Cover page

Sheet Unit costs
C2: Unit cost calculation
D4: Life time of the equipment | E4: 10
C5: Equipment cost (₤)
D6: Cost | E6: Maintenance costs (lifetime) | F6: Annual cost (lifetime = 10 years) | G6: Minimum annual procedures | H6: Cost per procedure
C7: FLIP | D7: 0 | E7: =3000*E4 -> 30000 | F7: =(E7+D7)/10 -> 3000 | G7: 200 | H7: =F7/G7 -> 15
C9: Consumable costs
D10: Cost | G10: Minimum annual procedures | H10: Cost per procedure
C11: Test kit | D11: 300 | G11: 200 | H11: =D11 -> 300
C13: Total cost per procedure | H13: =H11+H7 -> 315
S14: DOI 10.1007/s00464-012-2779-1
C15: Cost of treatment | M15: Inflation rate=3.5% | Q15: PPP in 2017 | R15: 1€ in DE = ₤0.8915
B16: Note | D16: Cost per case | E16: Maintenance costs (lifetime) | F16: Annual cost (lifetime = 10 years) | G16: Minimum annual procedures | H16: Cost per procedure | M16: 0.035 | O16: Costs in 2017 | Q16: 0.8915 | R16: Cost in Euros in 2017 | S16: Cost in GBP in 2017
C17: Treatment cost if developing PHLF (base case) | D17: =S17 -> 65997.466 | M17: Additional treatment costs for PHLF | N17: 56219 | O17: =N17*(1+M16)^8 -> 74029.687 | Q17: Additional treatment costs for PHLF | R17: =O17 -> 74029.687 | S17: =R17*Q16 -> 65997.466
C18: Treatment cost without PHLF and with regular recovery | D18: =S18 -> 5789.1793 | M18: Treatment cost without PHLF and with regular recovery | N18: =5593.41 -> 5593.41 | O18: =N18*(1+M16)^1 -> 5789.1793 | Q18: Treatment cost without PHLF and with regular recovery | R18: - | S18: =O18 -> 5789.1793
C20: Cost of additional staff time
B21: Note | C21: Role | D21: Required staff time with the LiMAx pathway (hrs) | E21: Cost per hour | F21: Cost in total
B22: 1* | C22: Staff time (band 5 nurse) ( 2 tests) | D22: 2 | E22: 45 | F22: =E22*D22 -> 90
C23: Total | F23: =SUM(F22:F22) -> 90
C25: The costs of overheads are not included in this analysis. Use of VeriQ leads to a small change in the length of a procedure, which will have a very small impact on overhead costs.
B29: References
B30: 1* | C30: Consultant – http://www.nhscareers.nhs.uk/details/Default.aspx?Id=553
B31: 2* | C31: Specialist doctor – http://www.nhscareers.nhs.uk/details/Default.aspx?Id=554
B32: 3* | C32: Mid-point band 6 Agenda for change 2011/12
B33: 4* | C33: Mid-point band 7 Agenda for change 2011/12

Sheet Input sheet
B1: Back to guide | G1: Column to be hidden
B2: Assumptions input | J2: Pathway
B4: The variables listed in the table below can be amended to reflect local circumstances. It is recommended that local users pay particular attention to the variables highlighted in bold. These have been identified as the significant cost drivers for this appraisal. If local data are not available the estimate made by NICE can be used. | J4: The pathway below shows the estimated numbers of patients and procedures that are affected by the NICE guidance. They are based on the assumptions made and the population selected.
J6: Current | K6: Future | L6: To sheet 6
B7: Variable narrative | C7: Source | D7: Base case | E7: Local Assumption | F7: Variance
B11: Total liver surgery episode | D11: 100 | E11: -
G12: =IF(OR(E11="-",E11=""),D11,E11) -> 100 | N12: =D11 -> 100 | AD12: =N12 -> 100
B14: Total number of the LiMAx procedures per operation | D14: 2 | E14: - | F14: -
G15: =IF(OR(E14="-",E14=""),D14,E14) -> 2 | N15: =N12*D14 -> 200 | AD15: =AD12*G15 -> 200
B17: Current incidence of PHLF | D17: 0.1 | E17: - | F17: =IF(OR(E17="-",E17=""),"-",E17-D17) -> -
G18: =IF(OR(E17="-",E17=""),D17,E17) -> 0.1 | K18: =ROUNDDOWN(N12*D17,0) -> 10 | AA18: =ROUNDDOWN(AD12*G18,0) -> 10
B20: Current regular recovery cases | D20: - | E20: - | F20: =IF(OR(E20="-",E20=""),"-",E20-D20) -> -
G21: =IF(OR(E20="-",E20=""),D20,E20) -> - | L21: =N12-K18 -> 90 | AB21: =AD12-AA18 -> 90
B23: Future incidence of PHLF | C23: 0.45 | D23: =D17*C23 -> 0.045 | E23: =IF(OR(E17="",E17="-"),"-",E17*C23) -> - | F23: =IF(OR(E23="-",E23=""),"-",E23-D23) -> -
G24: =IF(OR(E23="-",E23=""),D23,E23) -> 0.045 | Q24: =ROUNDDOWN(N12*D23,0) -> 4 | AG24: =ROUNDDOWN(AD12*G24,0) -> 4
B26: Future regular recovery | D26: - | E26: - | F26: =IF(OR(E26="-",E26=""),"-",E26-D26) -> -
G27: =IF(OR(E26="-",E26=""),D26,E26) -> - | P27: =N12-Q24 -> 96 | AF27: =AD12-AG24 -> 96
B30: Treatment cost if developing PHLF | D30: ='Unit costs'!D17 -> 65997.466 | E30: - | F30: =IF(OR(E30="-",E30=""),"-",E30-D30) -> - | G30: =IF(OR(E30="-",E30=""),D30,E30) -> 65997.466
B31: Treatment cost without PHLF | D31: ='Unit costs'!D18 -> 5789.1793 | F31: =IF(OR(E31="-",E31=""),"-",E31-D31) -> - | G31: =IF(OR(E31="-",E31=""),D31,E31) -> 5789.1793
B32: ='Unit costs'!C22 -> Staff time (band 5 nurse) ( 2 tests) | D32: ='Unit costs'!E22 -> 45 | F32: =IF(OR(E32="-",E32=""),"-",E32-D32) -> - | G32: =IF(OR(E32="-",E32=""),D32,E32) -> 45
B33: ='Unit costs'!C5 -> Equipment cost (₤) | D33: ='Unit costs'!H7 -> 15 | F33: =IF(OR(E33="-",E33=""),"-",E33-D33) -> - | G33: =IF(OR(E33="-",E33=""),D33,E33) -> 15
B34: ='Unit costs'!H10 -> Cost per procedure | D34: ='Unit costs'!H11 -> 300 | F34: =IF(OR(E34="-",E34=""),"-",E34-D34) -> - | G34: =IF(OR(E34="-",E34=""),D34,E34) -> 300

Sheet Costing template
B3: Costing template
D6: Cost for selected population using literature based assumptions | G6: Cost for selected population using local assumptions
B8: Notes | D8: Unit cost £ | E8: Units | F8: Sum £ | G8: Unit cost £ | H8: Units | I8: Sum £
C10: Total liver surgery episodes | E10: ='Input sheet'!N12 -> 100 | H10: ='Input sheet'!AD12 -> 100
C11: Number of people having a postoperative liver failure | E11: ='Input sheet'!K18 -> 10 | H11: ='Input sheet'!AA18 -> 10 | L11: Cost breakdown- selected population using literature based assumptions
L12: Current practice-cost of treating PHLF | N12: =D6 -> Cost for selected population using literature based assumptions | O12: =G6 -> Cost for selected population using local assumptions | Q12: Current practice-cost of liver surgery without PHLF | S12: Cost for selected population using literature based assumptions | T12: Cost for selected population using local assumptions
C13: Current practice | L13: Accommmodation | Q13: Accommmodation
M14: Ward | N14: =$F$15*'PHLF cost breakdown'!G4 -> 47403.047 | O14: =$I$15*'PHLF cost breakdown'!G4 -> 47403.047 | R14: Ward | S14: =$F$16*'PHLF cost breakdown'!E4 -> 161248.99 | T14: =$I$16*'PHLF cost breakdown'!E4 -> 161248.99
C15: Costs of treating liver surgery with PHLF | D15: ='Unit costs'!D17 -> 65997.466 | E15: =E11 -> 10 | F15: =E15*D15 -> 659974.66 | G15: ='Input sheet'!G30 -> 65997.466 | H15: =H11 -> 10 | I15: =H15*G15 -> 659974.66 | M15: ICU | N15: =$F$15*'PHLF cost breakdown'!G5 -> 340939.15 | O15: =$I$15*'PHLF cost breakdown'!G5 -> 340939.15 | R15: ICU | S15: =$F$16*'PHLF cost breakdown'!E5 -> 158401.41 | T15: =$I$16*'PHLF cost breakdown'!E5 -> 158401.41
C16: Cost of treating liver surgery without PHLF | D16: ='Unit costs'!D18 -> 5789.1793 | E16: =(E10-E11) -> 90 | F16: =E16*D16 -> 521026.14 | G16: ='Input sheet'!G31 -> 5789.1793 | H16: =H10-H15 -> 90 | I16: =H16*G16 -> 521026.14 | M16: Dialysis | N16: =$F$15*'PHLF cost breakdown'!G6 -> 46696.737 | O16: =$I$15*'PHLF cost breakdown'!G6 -> 46696.737 | R16: Dialysis | S16: =$F$16*'PHLF cost breakdown'!E6 -> 11550.73 | T16: =$I$16*'PHLF cost breakdown'!E6 -> 11550.73
L17: Treatment procedure | Q17: Treatment procedure
C18: Estimated costs of current practice | F18: =SUM(F14:F17) -> 1181000.8 | I18: =SUM(I14:I17) -> 1181000.8 | M18: Surgery | N18: =$F$15*'PHLF cost breakdown'!G8 -> 68616.432 | O18: =$I$15*'PHLF cost breakdown'!G8 -> 68616.432 | R18: Surgery | S18: =$F$16*'PHLF cost breakdown'!E8 -> 69364.538 | T18: =$I$16*'PHLF cost breakdown'!E8 -> 69364.538
C19: Future practice | M19: Anesthesia | N19: =$F$15*'PHLF cost breakdown'!G9 -> 32345.797 | O19: =$I$15*'PHLF cost breakdown'!G9 -> 32345.797 | R19: Anesthesia | S19: =$F$16*'PHLF cost breakdown'!E9 -> 30120.132 | T19: =$I$16*'PHLF cost breakdown'!E9 -> 30120.132
M20: Endoscopy | N20: =$F$15*'PHLF cost breakdown'!G10 -> 0 | O20: =$I$15*'PHLF cost breakdown'!G10 -> 0 | R20: Endoscopy | S20: =$F$16*'PHLF cost breakdown'!E10 -> 6437.1254 | T20: =$I$16*'PHLF cost breakdown'!E10 -> 6437.1254
C21: Total liver surgery episodes | E21: ='Input sheet'!N12 -> 100 | H21: ='Input sheet'!AD12 -> 100 | M21: Radiology | N21: =$F$15*'PHLF cost breakdown'!G11 -> 22521.664 | O21: =$I$15*'PHLF cost breakdown'!G11 -> 22521.664 | R21: Radiology | S21: =$F$16*'PHLF cost breakdown'!E11 -> 18388.922 | T21: =$I$16*'PHLF cost breakdown'!E11 -> 18388.922
C22: Number of people having a postoperative liver failure | E22: ='Input sheet'!Q24 -> 4 | H22: ='Input sheet'!AG24 -> 4 | M22: Lab | N22: =$F$15*'PHLF cost breakdown'!G12 -> 90584.285 | O22: =$I$15*'PHLF cost breakdown'!G12 -> 90584.285 | R22: Lab | S22: =$F$16*'PHLF cost breakdown'!E12 -> 53863.298 | T22: =$I$16*'PHLF cost breakdown'!E12 -> 53863.298
M23: Others | N23: =$F$15*'PHLF cost breakdown'!G13 -> 10867.546 | O23: =$I$15*'PHLF cost breakdown'!G13 -> 10867.546 | R23: Others | S23: =$F$16*'PHLF cost breakdown'!E13 -> 11650.996 | T23: =$I$16*'PHLF cost breakdown'!E13 -> 11650.996
L24: Total | N24: =SUM(N14:N23) -> 659974.66 | O24: =SUM(O14:O23) -> 659974.66 | Q24: Total | S24: =SUM(S14:S23) -> 521026.14 | T24: =SUM(T14:T23) -> 521026.14
C25: Costs of technology adoption
C26: Equipment costs for the LiMAx test | D26: ='Unit costs'!H7 -> 15 | E26: ='Unit costs'!G7 -> 200 | F26: =E26*D26 -> 3000 | G26: ='Input sheet'!G33 -> 15 | H26: ='Unit costs'!G7 -> 200 | I26: =H26*G26 -> 3000 | L26: Future practice-cost of treating PHLF | N26: Cost for selected population using literature based assumptions | O26: Cost for selected population using local assumptions | Q26: Future practice-cost of liver surgery without PHLF | S26: Cost for selected population using literature based assumptions | T26: Cost for selected population using local assumptions
C27: Additional staff time costs due to using LiMAx testing | D27: ='Unit costs'!E22 -> 45 | E27: ='Unit costs'!G11 -> 200 | F27: =E27*D27 -> 9000 | G27: ='Input sheet'!G32 -> 45 | H27: ='Unit costs'!G11 -> 200 | I27: =H27*G27 -> 9000 | L27: Accommmodation | Q27: Accommmodation
C28: Costs of performing LiMAx procedures | D28: ='Unit costs'!D11 -> 300 | E28: ='Unit costs'!G11 -> 200 | F28: =E28*D28 -> 60000 | G28: ='Input sheet'!G34 -> 300 | H28: ='Unit costs'!G11 -> 200 | I28: =H28*G28 -> 60000 | M28: Ward | N28: =$F$30*'PHLF cost breakdown'!G4 -> 18961.219 | O28: =$I$30*'PHLF cost breakdown'!G4 -> 18961.219 | R28: Ward | S28: =$F$31*'PHLF cost breakdown'!E4 -> 171998.92 | T28: =$I$31*'PHLF cost breakdown'!E4 -> 171998.92
M29: ICU | N29: =$F$30*'PHLF cost breakdown'!G5 -> 136375.66 | O29: =$I$30*'PHLF cost breakdown'!G5 -> 136375.66 | R29: ICU | S29: =$F$31*'PHLF cost breakdown'!E5 -> 168961.51 | T29: =$I$31*'PHLF cost breakdown'!E5 -> 168961.51
C30: Costs of treating liver surgery with PHLF | D30: ='Unit costs'!D17 -> 65997.466 | E30: ='Input sheet'!Q24 -> 4 | F30: =E30*D30 -> 263989.86 | G30: ='Input sheet'!G30 -> 65997.466 | H30: ='Input sheet'!AG24 -> 4 | I30: =H30*G30 -> 263989.86 | M30: Dialysis | N30: =$F$30*'PHLF cost breakdown'!G6 -> 18678.695 | O30: =$I$30*'PHLF cost breakdown'!G6 -> 18678.695 | R30: Dialysis | S30: =$F$31*'PHLF cost breakdown'!E6 -> 12320.778 | T30: =$I$31*'PHLF cost breakdown'!E6 -> 12320.778
C31: Cost of treating liver surgery without PHLF | D31: ='Unit costs'!D18 -> 5789.1793 | E31: =E21-E30 -> 96 | F31: =E31*D31 -> 555761.22 | G31: ='Input sheet'!G31 -> 5789.1793 | H31: =H21-H30 -> 96 | I31: =H31*G31 -> 555761.22 | L31: Treatment procedure | Q31: Treatment procedure
M32: Surgery | N32: =$F$30*'PHLF cost breakdown'!G8 -> 27446.573 | O32: =$I$30*'PHLF cost breakdown'!G8 -> 27446.573 | R32: Surgery | S32: =$F$31*'PHLF cost breakdown'!E8 -> 73988.84 | T32: =$I$31*'PHLF cost breakdown'!E8 -> 73988.84
M33: Anesthesia | N33: =$F$30*'PHLF cost breakdown'!G9 -> 12938.319 | O33: =$I$30*'PHLF cost breakdown'!G9 -> 12938.319 | R33: Anesthesia | S33: =$F$31*'PHLF cost breakdown'!E9 -> 32128.141 | T33: =$I$31*'PHLF cost breakdown'!E9 -> 32128.141
C34: Estimated costs of future practice | F34: =SUM(F19:F33) -> 891751.08 | I34: =SUM(I19:I33) -> 891751.08 | M34: Endoscopy | N34: =$F$30*'PHLF cost breakdown'!G10 -> 0 | O34: =$I$30*'PHLF cost breakdown'!G10 -> 0 | R34: Endoscopy | S34: =$F$31*'PHLF cost breakdown'!E10 -> 6866.2671 | T34: =$I$31*'PHLF cost breakdown'!E10 -> 6866.2671
M35: Radiology | N35: =$F$30*'PHLF cost breakdown'!G11 -> 9008.6658 | O35: =$I$30*'PHLF cost breakdown'!G11 -> 9008.6658 | R35: Radiology | S35: =$F$31*'PHLF cost breakdown'!E11 -> 19614.85 | T35: =$I$31*'PHLF cost breakdown'!E11 -> 19614.85
C36: Net resource impact | F36: =F34-F18 -> -289249.72 | I36: =I34-I18 -> -289249.72 | M36: Lab | N36: =$F$30*'PHLF cost breakdown'!G12 -> 36233.714 | O36: =$I$30*'PHLF cost breakdown'!G12 -> 36233.714 | R36: Lab | S36: =$F$31*'PHLF cost breakdown'!E12 -> 57454.185 | T36: =$I$31*'PHLF cost breakdown'!E12 -> 57454.185
C37: Net resource impact per operation | F37: =F36/E21 -> -2892.4972 | I37: =I36/H21 -> -2892.4972 | M37: Others | N37: =$F$30*'PHLF cost breakdown'!G13 -> 4347.0183 | O37: =$I$30*'PHLF cost breakdown'!G13 -> 4347.0183 | R37: Others | S37: =$F$31*'PHLF cost breakdown'!E13 -> 12427.729 | T37: =$I$31*'PHLF cost breakdown'!E13 -> 12427.729
L38: Total | N38: =SUM(N28:N37) -> 263989.86 | O38: =SUM(O28:O37) -> 263989.86 | Q38: Total | S38: =SUM(S28:S37) -> 555761.22 | T38: =SUM(T28:T37) -> 555761.22
C41: Cost-saving of avoiding PHLF | E41: Savings | H41: Savings
C42: Accommmodation
D43: Ward | E43: =N14+S14-N28-S28 -> 17691.896 | G43: Ward | H43: =O14+T14-O28-T28 -> 17691.896
D44: ICU | E44: =N15+S15-N29-S29 -> 194003.4 | G44: ICU | H44: =O15+T15-O29-T29 -> 194003.4
D45: Dialysis | E45: =N16+S16-N30-S30 -> 27247.993 | G45: Dialysis | H45: =O16+T16-O30-T30 -> 27247.993
C46: Treatment procedure
D47: Surgery | E47: =N18+S18-N32-S32 -> 36545.557 | G47: Surgery | H47: =O18+T18-O32-T32 -> 36545.557
D48: Anesthesia | E48: =N19+S19-N33-S33 -> 17399.47 | G48: Anesthesia | H48: =O19+T19-O33-T33 -> 17399.47
...

Sheet Costing report
B2: Back to guide
C7: Costing report: the LiMAx test for assessing liver function before and after liver surgery
B9: Introduction
B10: Medical technologies guidance is designed to help the NHS adopt efficient and cost effective medical devices more rapidly and consistently. The types of products that might be evaluated are medical devices that deliver treatment, such as those implanted during surgical procedures, technologies that give greater independence to patients, and diagnostic devices or tests used to detect or monitor medical conditions.
B12: This document supports the implementation of the guidance.
B14: The costing template can be used to estimate the local cost and saving implications of implementing the guidance. By varying the assumptions and feeding in data that reflect local circumstances, the local estimated cost and saving implications can be calculated. The national costing report illustrates the broader implications for the NHS. It is derived from the same template, but using national data. A summary for each of these reports is shown below.
B16: Background of this medical technology guidance
B17: Coronary artery disease is a common cause of symptoms, disability and death. It is caused by atherosclerosis, which leads to stenosis or occlusion of the coronary arteries. NICE clinical guideline 126 'Management of stable angina' recommends that revascularisation of the blocked coronary arteries using coronary artery bypass graft (CABG) or percutaneous coronary intervention should be considered in people whose symptoms are not satisfactorily controlled with optimal medical treatment.
B18: CABG aims to bypass narrowed or blocked segments of the coronary arteries using grafts – usually lengths of the patient’s own long saphenous vein from the leg or their internal thoracic artery, although other vessels are also used. Cardiac surgeons use a variety of techniques to avoid imperfections during CABG, but assessment of graft flow is usually subjective. Techniques used vary according to the graft constructed, the surgical technique, and the surgeon’s individual preference. They include the surgeon assessing resistance and perfusion beyond a graft by flushing fluid through it before restoring flow, and both observing and palpating grafts for pulsation when blood flow has been re-established.
B19: The VeriQ system (MediStim ASA) uses ultrasound for the non-invasive assessment of graft blood flow during CABG surgery. It is intended for use in patients with coronary artery disease who are having CABG surgery.
B20: The claimed benefits of the VeriQ system in the case for adoption presented by the manufacturer are: • improved outcomes of revascularisation procedures by reducing the risk of early graft failure and adverse events • reduced hospital stay for some patients by reducing the incidence of complications during and after surgery • reduced number of repeat procedures and treatments for post-operative complications.
B22: Guidance
B23: 1.1 The case for adopting the VeriQ system in the NHS for assessing graft flow during coronary artery bypass graft (CABG) surgery is supported by the evidence. The evidence suggests that intra-operative transit time flow measurement is effective in detecting imperfections that may be corrected by graft revision. This may reduce the incidence of graft occlusion and may reduce perioperative morbidity and mortality. 1.2 The VeriQ system is associated with an estimated cost saving of £115 per patient compared with clinical assessment, when it is used routinely for assessing coronary artery bypass grafts during surgery.
B25: Costing summary
B26: The annual saving associated with implementing this guidance is estimated as £1.4 million for the total population of England, based on the standard assumptions in the model.
C28: Cost of implementation for the total population of England - NICE assumptions | D28: Cost / -saving (£)
C29: Additional cost of equipment and surgery time due to using VeriQ | D29: 1203723.4
C30: Savings due to reduction in adverse events | D30: -2578270
C31: Total cost / -saving | D31: -1374546.6
C32: Total cost / -saving per procedure | D32: -146.81797
B34: The average cost saving per procedure calculated in this template is £147, which is higher than the £115 calculated in the clinical and economic external assessment centre report. The calculations in this template use more recent figures for hospital activity and, if available, national tariff rather than reference costs for the unit costs of adverse events. Users are advised to check the assumptions made against the latest local information available when using the costing template.
B36: After adapting the assumptions in the costing template to reflect local circumstances and selecting the local population, the estimated cost of fully implementing this recommendation locally is summarised below.
B38: Unless a population is selected in sheet 4 'Population selection', the default population used is 1,000,000.
C40: Cost of implementation for selected population - local assumptions | D40: Cost / -saving (£)
C41: Additional cost of equipment and surgery time due to using VeriQ | D41: =SUM(#REF!)-SUM(#REF!) -> #REF!
C42: Savings due to reduction in adverse events | D42: =SUM(#REF!)-SUM(#REF!) -> #REF!
C43: Total cost / -saving | D43: =SUM(D41:D42) -> #REF!
C44: Total cost / -saving per procedure | D44: =#REF! -> #REF!
B47: Summary of sensitivity analysis
B48: The variables to which the model is most sensitive are:
B49: • | C49: =#REF! -> #REF!
B50: • | C50: =#REF! -> #REF!
B51: • | C51: =#REF! -> #REF!
B52: The savings identified are most sensitive to the cost of intra-aortic balloon pumping and the reduction in occurrence of intra-aortic balloon pumping following use of VeriQ. The sensitivity analysis shows that varying these inputs has the largest effect on the overall cost savings, however, it should be noted that even in the worst case identified in the sensitivity analysis, the use of VeriQ is still expected to be cost saving.
B53: The level of savings is directly affected by the total number of CABG procedures taking place in a year and the proportion of procedures for which the device is used. If VeriQ is not used for all procedures, the maximum benefit will not be achieved and therefore savings are reduced. This assumption should be amended on sheet 6 to reflect local circumstances.
B56: Other considerations
B57: There may be additional indications for which the VeriQ device can be used such as valve repairs or in transplants, which could reduce the capital cost per procedure, however, these uses have not been considered in the guidance or costing template.
B58: The number of cardiac centres purchasing VeriQ following publication of this guidance is very difficult to predict as it will largely be down to the views of clinicians and managers locally. It is estimated that nationally, 50% of CABG procedures will use VeriQ following publication of this guidance. This should be adapted for local use.
B59: Purchase of VeriQ would need a capital investment which is not quantified in this template as it is included in the average cost of a CABG procedure used. However given the purchase price of £32,000 this is simple to calculate for any locality. There is also the option to lease the equipment.
B61: Savings and benefits
...

Sheet Average cost reported all
A1: 2014/15 Patient Level Costing and Information Systems (PLICS) data collection summary: summary statistics on Total Cost by HRG, Point of Delivery
A2: 2014/15 Reference Cost Grouper - FCE HRG | B2: HRG Description | C2: POD | D2: POD Description | E2: Finished Consultant Episode (FCE) count | F2: % of total cases | G2: Local finished episode count (base case) | H2: Local finished episode count (local case) | I2: Avg Finished Consultant Episode cost | J2: Total Finished Consultant Episode cost (base case) | K2: Total Finished Consultant Episode cost (local case) | L2: Standard Deviation | M2: Minimum | N2: 25th percentile | O2: Median | P2: 75th percentile | Q2: Maximum | R2: Relative Standard Deviation | S2: Average of Trust-level Relative Standard Deviation
A3: GA03C | B3: Very Complex Open, Hepatobiliary or Pancreatic Procedures, with CC Score 4+ | C3: EL | D3: Elective | E3: 263 | F3: =E3/$E$36 -> 0.042039642 | G3: =F3*$G$36 -> 4.2039642 | H3: =$G$37*F3 -> 4.2039642 | I3: 26412.93 | J3: =G3*I3 -> 111039.01 | K3: =I3*H3 -> 111039.01 | L3: 25548.96 | M3: 426.47 | N3: 13710.22 | O3: 19889.37 | P3: 29031.75 | Q3: 200000 | R3: =IFERROR(L3/I3,"") -> 0.96728988 | S3: 0.73866763
A4: GA03C | B4: Very Complex Open, Hepatobiliary or Pancreatic Procedures, with CC Score 4+ | C4: NE | D4: Non Elective | E4: 205 | F4: =E4/$E$36 -> 0.032768542 | G4: =F4*$G$36 -> 3.2768542 | H4: =$G$37*F4 -> 3.2768542 | I4: 14016.91 | J4: =G4*I4 -> 45931.371 | K4: =I4*H4 -> 45931.371 | L4: 18098.95 | M4: 90.3 | N4: 3609.01 | O4: 8092.27 | P4: 18699.56 | Q4: 150000 | R4: =IFERROR(L4/I4,"") -> 1.2912225 | S4: 0.78778239
A5: GA03D | B5: Very Complex Open, Hepatobiliary or Pancreatic Procedures, with CC Score 2-3 | C5: EL | D5: Elective | E5: 281 | F5: =E5/$E$36 -> 0.04491688 | G5: =F5*$G$36 -> 4.491688 | H5: =$G$37*F5 -> 4.491688 | I5: 16344.69 | J5: =G5*I5 -> 73415.248 | K5: =I5*H5 -> 73415.248 | L5: 8232.02 | M5: 189.88 | N5: 10475.43 | O5: 14914.67 | P5: 21066.97 | Q5: 43773.56 | R5: =IFERROR(L5/I5,"") -> 0.50365103 | S5: 0.4099595
A6: GA03D | B6: Very Complex Open, Hepatobiliary or Pancreatic Procedures, with CC Score 2-3 | C6: NE | D6: Non Elective | E6: 106 | F6: =E6/$E$36 -> 0.016943734 | G6: =F6*$G$36 -> 1.6943734 | H6: =$G$37*F6 -> 1.6943734 | I6: 9799.15 | J6: =G6*I6 -> 16603.419 | K6: =I6*H6 -> 16603.419 | L6: 10213.85 | M6: 335.25 | N6: 3303.97 | O6: 6489.27 | P6: 12941.7 | Q6: 55636.46 | R6: =IFERROR(L6/I6,"") -> 1.04232 | S6: 0.60855952
A7: GA03E | B7: Very Complex Open, Hepatobiliary or Pancreatic Procedures, with CC Score 0-1 | C7: EL | D7: Elective | E7: 509 | F7: =E7/$E$36 -> 0.081361893 | G7: =F7*$G$36 -> 8.1361893 | H7: =$G$37*F7 -> 8.1361893 | I7: 13681.54 | J7: =G7*I7 -> 111315.6 | K7: =I7*H7 -> 111315.6 | L7: 7911.94 | M7: 0 | N7: 9654.81 | O7: 12275.36 | P7: 16626.71 | Q7: 81435.58 | R7: =IFERROR(L7/I7,"") -> 0.57829309 | S7: 0.44384115
A8: GA03E | B8: Very Complex Open, Hepatobiliary or Pancreatic Procedures, with CC Score 0-1 | C8: NE | D8: Non Elective | E8: 119 | F8: =E8/$E$36 -> 0.019021739 | G8: =F8*$G$36 -> 1.9021739 | H8: =$G$37*F8 -> 1.9021739 | I8: 7802.41 | J8: =G8*I8 -> 14841.541 | K8: =I8*H8 -> 14841.541 | L8: 7613.36 | M8: 233.32 | N8: 2878.18 | O8: 5220.78 | P8: 10431.87 | Q8: 47890.18 | R8: =IFERROR(L8/I8,"") -> 0.97577031 | S8: 0.60494205
A9: GA03E | B9: Very Complex Open, Hepatobiliary or Pancreatic Procedures, with CC Score 0-1 | C9: DC | D9: Day Case | E9: 3 | F9: =E9/$E$36 -> 0.00047953964 | G9: =F9*$G$36 -> 0.047953964 | H9: =$G$37*F9 -> 0.047953964 | I9: 2880.75 | J9: =G9*I9 -> 138.14338 | K9: =I9*H9 -> 138.14338 | L9: 2700.74 | M9: 1239.34 | N9: 1239.34 | O9: 1405.09 | P9: 5997.83 | Q9: 5997.83 | R9: =IFERROR(L9/I9,"") -> 0.9375128
A10: GA04C | B10: Complex Open, Hepatobiliary or Pancreatic Procedures, with CC Score 3+ | C10: EL | D10: Elective | E10: 214 | F10: =E10/$E$36 -> 0.034207161 | G10: =F10*$G$36 -> 3.4207161 | H10: =$G$37*F10 -> 3.4207161 | I10: 20466.12 | J10: =G10*I10 -> 70008.786 | K10: =I10*H10 -> 70008.786 | L10: 26518.81 | M10: 311.12 | N10: 9968.29 | O10: 14642.74 | P10: 21100.09 | Q10: 220000 | R10: =IFERROR(L10/I10,"") -> 1.2957419 | S10: 0.66629376
A11: GA04C | B11: Complex Open, Hepatobiliary or Pancreatic Procedures, with CC Score 3+ | C11: NE | D11: Non Elective | E11: 27 | F11: =E11/$E$36 -> 0.0043158568 | G11: =F11*$G$36 -> 0.43158568 | H11: =$G$37*F11 -> 0.43158568 | I11: 29737.54 | J11: =G11*I11 -> 12834.296 | K11: =I11*H11 -> 12834.296 | L11: 37071.96 | M11: 526.7 | N11: 11294.13 | O11: 16301.42 | P11: 33206.54 | Q11: 170000 | R11: =IFERROR(L11/I11,"") -> 1.2466384 | S11: 0.63373772
A12: GA04D | B12: Complex Open, Hepatobiliary or Pancreatic Procedures, with CC Score 0-2 | C12: EL | D12: Elective | E12: 591 | F12: =E12/$E$36 -> 0.094469309 | G12: =F12*$G$36 -> 9.4469309 | H12: =$G$37*F12 -> 9.4469309 | I12: 11708.38 | J12: =G12*I12 -> 110608.26 | K12: =I12*H12 -> 110608.26 | L12: 5933.04 | M12: -8012.56 | N12: 8461.12 | O12: 10940.5 | P12: 13960.25 | Q12: 62160.75 | R12: =IFERROR(L12/I12,"") -> 0.50673449 | S12: 0.45291975
A13: GA04D | B13: Complex Open, Hepatobiliary or Pancreatic Procedures, with CC Score 0-2 | C13: NE | D13: Non Elective | E13: 21 | F13: =E13/$E$36 -> 0.0033567775 | G13: =F13*$G$36 -> 0.33567775 | H13: =$G$37*F13 -> 0.33567775 | I13: 20357.73 | J13: =G13*I13 -> 6833.637 | K13: =I13*H13 -> 6833.637 | L13: 25053.09 | M13: 421.17 | N13: 7508.09 | O13: 15018.14 | P13: 21238.07 | Q13: 120000 | R13: =IFERROR(L13/I13,"") -> 1.2306426 | S13: 0.73767748
A14: GA04D | B14: Complex Open, Hepatobiliary or Pancreatic Procedures, with CC Score 0-2 | C14: DC | D14: Day Case | E14: 1 | F14: =E14/$E$36 -> 0.00015984655 | G14: =F14*$G$36 -> 0.015984655 | H14: =$G$37*F14 -> 0.015984655 | I14: 1441.72 | J14: =G14*I14 -> 23.045396 | K14: =I14*H14 -> 23.045396 | L14: . | M14: 1441.72 | N14: 1441.72 | O14: 1441.72 | P14: 1441.72 | Q14: 1441.72 | R14: =IFERROR(L14/I14,"")
A15: GA05C | B15: Very Major Open, Hepatobiliary or Pancreatic Procedures, with CC Score 3+ | C15: EL | D15: Elective | E15: 297 | F15: =E15/$E$36 -> 0.047474425 | G15: =F15*$G$36 -> 4.7474425 | H15: =$G$37*F15 -> 4.7474425 | I15: 12596.69 | J15: =G15*I15 -> 59802.061 | K15: =I15*H15 -> 59802.061 | L15: 13099.34 | M15: 87.06 | N15: 7001.54 | O15: 9340.25 | P15: 13638.68 | Q15: 140000 | R15: =IFERROR(L15/I15,"") -> 1.0399033 | S15: 0.55242303
A16: GA05C | B16: Very Major Open, Hepatobiliary or Pancreatic Procedures, with CC Score 3+ | C16: NE | D16: Non Elective | E16: 92 | F16: =E16/$E$36 -> 0.014705882 | G16: =F16*$G$36 -> 1.4705882 | H16: =$G$37*F16 -> 1.4705882 | I16: 14659.82 | J16: =G16*I16 -> 21558.559 | K16: =I16*H16 -> 21558.559 | L16: 19049.24 | M16: 125.12 | N16: 4355.65 | O16: 8621.45 | P16: 16216.93 | Q16: 150000 | R16: =IFERROR(L16/I16,"") -> 1.2994184 | S16: 0.68264152
A17: GA05C | B17: Very Major Open, Hepatobiliary or Pancreatic Procedures, with CC Score 3+ | C17: DC | D17: Day Case | E17: 2 | F17: =E17/$E$36 -> 0.00031969309 | G17: =F17*$G$36 -> 0.031969309 | H17: =$G$37*F17 -> 0.031969309 | I17: 768.99 | J17: =G17*I17 -> 24.584079 | K17: =I17*H17 -> 24.584079 | L17: 814.09 | M17: 193.34 | N17: 193.34 | O17: 768.99 | P17: 1344.64 | Q17: 1344.64 | R17: =IFERROR(L17/I17,"") -> 1.0586484
A18: GA05D | B18: Very Major Open, Hepatobiliary or Pancreatic Procedures, with CC Score 0-2 | C18: EL | D18: Elective | E18: 946 | F18: =E18/$E$36 -> 0.15121483 | G18: =F18*$G$36 -> 15.121483 | H18: =$G$37*F18 -> 15.121483 | I18: 8980.89 | J18: =G18*I18 -> 135804.38 | K18: =I18*H18 -> 135804.38 | L18: 4569.95 | M18: 34.62 | N18: 6130.22 | O18: 8374.97 | P18: 11063.66 | Q18: 34232.11 | R18: =IFERROR(L18/I18,"") -> 0.50885269 | S18: 0.45578476
A19: GA05D | B19: Very Major Open, Hepatobiliary or Pancreatic Procedures, with CC Score 0-2 | C19: NE | D19: Non Elective | E19: 102 | F19: =E19/$E$36 -> 0.016304348 | G19: =F19*$G$36 -> 1.6304348 | H19: =$G$37*F19 -> 1.6304348 | I19: 7700.46 | J19: =G19*I19 -> 12555.098 | K19: =I19*H19 -> 12555.098 | L19: 8831.08 | M19: 67.76 | N19: 3312.55 | O19: 5953.68 | P19: 9719.6 | Q19: 79376.79 | R19: =IFERROR(L19/I19,"") -> 1.146825 | S19: 0.57714792
A20: GA05D | B20: Very Major Open, Hepatobiliary or Pancreatic Procedures, with CC Score 0-2 | C20: DC | D20: Day Case | E20: 40 | F20: =E20/$E$36 -> 0.0063938619 | G20: =F20*$G$36 -> 0.63938619 | H20: =$G$37*F20 -> 0.63938619 | I20: 905.68 | J20: =G20*I20 -> 579.07928 | K20: =I20*H20 -> 579.07928 | L20: 752.74 | M20: 22.83 | N20: 347.66 | O20: 823.72 | P20: 1127.96 | Q20: 3577.14 | R20: =IFERROR(L20/I20,"") -> 0.83113241 | S20: 0.39124003
A21: GA06C | B21: Major Open, Hepatobiliary or Pancreatic Procedures, with CC Score 2+ | C21: EL | D21: Elective | E21: 164 | F21: =E21/$E$36 -> 0.026214834 | G21: =F21*$G$36 -> 2.6214834 | H21: =$G$37*F21 -> 2.6214834 | I21: 9406.51 | J21: =G21*I21 -> 24659.01 | K21: =I21*H21 -> 24659.01 | L21: 8676.89 | M21: 127.34 | N21: 4382.74 | O21: 7369.78 | P21: 11439.25 | Q21: 52868.1 | R21: =IFERROR(L21/I21,"") -> 0.92243457 | S21: 0.62586068
A22: GA06C | B22: Major Open, Hepatobiliary or Pancreatic Procedures, with CC Score 2+ | C22: NE | D22: Non Elective | E22: 101 | F22: =E22/$E$36 -> 0.016144501 | G22: =F22*$G$36 -> 1.6144501 | H22: =$G$37*F22 -> 1.6144501 | I22: 11436.16 | J22: =G22*I22 -> 18463.11 | K22: =I22*H22 -> 18463.11 | L22: 15397.13 | M22: 146.84 | N22: 3270.89 | O22: 7813.55 | P22: 12771.87 | Q22: 120000 | R22: =IFERROR(L22/I22,"") -> 1.3463549 | S22: 0.75727863
A23: GA06C | B23: Major Open, Hepatobiliary or Pancreatic Procedures, with CC Score 2+ | C23: DC | D23: Day Case | E23: 18 | F23: =E23/$E$36 -> 0.0028772379 | G23: =F23*$G$36 -> 0.28772379 | H23: =$G$37*F23 -> 0.28772379 | I23: 1152.27 | J23: =G23*I23 -> 331.53549 | K23: =I23*H23 -> 331.53549 | L23: 1327.97 | M23: 254.41 | N23: 613.52 | O23: 767.74 | P23: 1030.01 | Q23: 5696.33 | R23: =IFERROR(L23/I23,"") -> 1.1524816 | S23: 0.34676909
A24: GA06D | B24: Major Open, Hepatobiliary or Pancreatic Procedures, with CC Score 0-1 | C24: EL | D24: Elective | E24: 257 | F24: =E24/$E$36 -> 0.041080563 | G24: =F24*$G$36 -> 4.1080563 | H24: =$G$37*F24 -> 4.1080563 | I24: 6037.03 | J24: =G24*I24 -> 24800.459 | K24: =I24*H24 -> 24800.459 | L24: 4619.21 | M24: 109.89 | N24: 2390.52 | O24: 5171.98 | P24: 8554.98 | Q24: 26259.35 | R24: =IFERROR(L24/I24,"") -> 0.76514611 | S24: 0.55406534
A25: GA06D | B25: Major Open, Hepatobiliary or Pancreatic Procedures, with CC Score 0-1 | C25: NE | D25: Non Elective | E25: 67 | F25: =E25/$E$36 -> 0.010709719 | G25: =F25*$G$36 -> 1.0709719 | H25: =$G$37*F25 -> 1.0709719 | I25: 6709.26 | J25: =G25*I25 -> 7185.4287 | K25: =I25*H25 -> 7185.4287 | L25: 6387.72 | M25: 107.45 | N25: 2169.81 | O25: 4841.41 | P25: 9055.36 | Q25: 40610.46 | R25: =IFERROR(L25/I25,"") -> 0.95207519 | S25: 0.57571414
A26: GA06D | B26: Major Open, Hepatobiliary or Pancreatic Procedures, with CC Score 0-1 | C26: DC | D26: Day Case | E26: 95 | F26: =E26/$E$36 -> 0.015185422 | G26: =F26*$G$36 -> 1.5185422 | H26: =$G$37*F26 -> 1.5185422 | I26: 918.86 | J26: =G26*I26 -> 1395.3277 | K26: =I26*H26 -> 1395.3277 | L26: 816.84 | M26: 138.48 | N26: 508.47 | O26: 615.73 | P26: 1079.3 | Q26: 4180.9 | R26: =IFERROR(L26/I26,"") -> 0.88897112 | S26: 0.44870017
A27: GA07C | B27: Intermediate Open, Hepatobiliary or Pancreatic Procedures, with CC Score 3+ | C27: EL | D27: Elective | E27: 175 | F27: =E27/$E$36 -> 0.027973146 | G27: =F27*$G$36 -> 2.7973146 | H27: =$G$37*F27 -> 2.7973146 | I27: 7072.12 | J27: =G27*I27 -> 19782.944 | K27: =I27*H27 -> 19782.944 | L27: 7601.13 | M27: 10.84 | N27: 3529.92 | O27: 5592.84 | P27: 8459.22 | Q27: 73871.1 | R27: =IFERROR(L27/I27,"") -> 1.0748022 | S27: 0.61942555
A28: GA07C | B28: Intermediate Open, Hepatobiliary or Pancreatic Procedures, with CC Score 3+ | C28: NE | D28: Non Elective | E28: 185 | F28: =E28/$E$36 -> 0.029571611 | G28: =F28*$G$36 -> 2.9571611 | H28: =$G$37*F28 -> 2.9571611 | I28: 10177.36 | J28: =G28*I28 -> 30096.093 | K28: =I28*H28 -> 30096.093 | L28: 16838.12 | M28: 41.84 | N28: 3059.68 | O28: 6002.79 | P28: 10700.32 | Q28: 170000 | R28: =IFERROR(L28/I28,"") -> 1.6544683 | S28: 0.70185872
A29: GA07C | B29: Intermediate Open, Hepatobiliary or Pancreatic Procedures, with CC Score 3+ | C29: DC | D29: Day Case | E29: 11 | F29: =E29/$E$36 -> 0.001758312 | G29: =F29*$G$36 -> 0.1758312 | H29: =$G$37*F29 -> 0.1758312 | I29: 1573.08 | J29: =G29*I29 -> 276.59655 | K29: =I29*H29 -> 276.59655 | L29: 1541.17 | M29: 254.41 | N29: 464.48 | O29: 836.07 | P29: 2578.2 | Q29: 5002.65 | R29: =IFERROR(L29/I29,"") -> 0.97971495 | S29: 0.54843972
... A35: GA07E | B35: Intermediate Open, Hepatobiliary or Pancreatic Procedures, with CC Score 0 | C35: DC | D35: Day Case | E35: 128 | F35: =E35/$E$36 -> 0.020460358 | G35: =F35*$G$36 -> 2.0460358 | H35: =$G$37*F35 -> 2.0460358 | I35: 1775.21 | J35: =G35*I35 -> 3632.1432 | K35: =I35*H35 -> 3632.1432 | L35: 1680.11 | M35: 76.46 | N35: 669.02 | O35: 1374.92 | P35: 2337.02 | Q35: 11920.72 | R35: =IFERROR(L35/I35,"") -> 0.94642887 | S35: 0.55341948
E36: =SUM(E3:E35) -> 6256 | F36: Base case FCE | G36: ='Input sheet'!N12 -> 100 | I36: Total costs (base case) | J36: =SUM(J3:J35) -> 1036385.6
F37: Local FCE | G37: ='Input sheet'!AD12 -> 100 | I37: Total costs (local case) | J37: =SUM(K3:K35) -> 1036385.6

Sheet PHLF cost breakdown
D2: Cost of regular recovery | E2: Percentage of total costs | F2: Cost of PHLF | G2: Percentage of total costs
B3: Accommmodation
C4: Ward | D4: 8041 | E4: =D4/$D$14 -> 0.30948349 | F4: 5906 | G4: =F4/$F$14 -> 0.071825556
C5: ICU | D5: 7899 | E5: =D5/$D$14 -> 0.30401817 | F5: 42478 | G5: =F5/$F$14 -> 0.51659431
C6: Dialysis | D6: 576 | E6: =D6/$D$14 -> 0.022169194 | F6: 5818 | G6: =F6/$F$14 -> 0.070755348
B7: Treatment procedure
C8: Surgery | D8: 3459 | E8: =D8/$D$14 -> 0.13313063 | F8: 8549 | G8: =F8/$F$14 -> 0.10396828
C9: Anesthesia | D9: 1502 | E9: =D9/$D$14 -> 0.057809253 | F9: 4030 | G9: =F9/$F$14 -> 0.049010666
C10: Endoscopy | D10: 321 | E10: =D10/$D$14 -> 0.012354707 | F10: 0 | G10: =F10/$F$14 -> 0
C11: Radiology | D11: 917 | E11: =D11/$D$14 -> 0.035293665 | F11: 2806 | G11: =F11/$F$14 -> 0.034125044
C12: Lab | D12: 2686 | E12: =D12/$D$14 -> 0.10337926 | F12: 11286 | G12: =F12/$F$14 -> 0.13725419
C13: Others | D13: 581 | E13: =D13/$D$14 -> 0.022361635 | F13: 1354 | G13: =F13/$F$14 -> 0.016466611
B14: Total | D14: =SUM(D4:D13) -> 25982 | F14: =SUM(F4:F13) -> 82227

Sheet Cost pool breakdown
A1: 2014/15 Patient Level Costing and Information Systems (PLICS) data collection summary: average cost pool by HRG and Point of Delivery | O1: Average Finished Consultant Episode cost - cost pool breakdown:
N2: Sum of 1 to 27 | O2: 1 | P2: =O2+1 -> 2 | Q2: =P2+1 -> 3 | R2: =Q2+1 -> 4 | S2: =R2+1 -> 5 | T2: =S2+1 -> 6 | U2: =T2+1 -> 7 | V2: =U2+1 -> 8 | W2: =V2+1 -> 9 | ... AO2: =AN2+1 -> 27
A3: 2014/15 Reference Cost Grouper - FCE HRG | B3: HRG Description | C3: POD | D3: POD Description | E3: No. of Providers Submitted | F3: Finished Consultant Episode (FCE) count | G3: Avg FCE LOS (Days) | H3: FCEs with theatre time recorded | I3: Avg theatre time (Minutes) (where recorded) | J3: FCEs with critical care LOS recorded | K3: Avg critical care LOS (Hours) (where recorded) | L3: FCEs with endoscopy time (Minutes) recorded | M3: Avg endoscopy time (Minutes) (where recorded) | N3: Avg Finished Consultant Episode cost | O3: Blood and Blood Products | P3: CNST | Q3: Critical Care | R3: High Cost Drugs | S3: Chemotherapy Drugs | T3: All Other Drugs | U3: Emergency Department | V3: Imaging - Medical Staffing | W3: Imaging - All Other Costs | X3: Medical Staffing (excluding Imaging, Pathology & Other Diagnostics) | Y3: Operating Theatres | Z3: Other Clinical Supplies and Services | AA3: Other Diagnostics Tests - Medical Staffing | AB3: Other Diagnostics Tests- All Other Costs | AC3: Outpatients | AD3: Pathology- Medical Staffing | AE3: Pathology- All Other Costs | AF3: Pharmacy Services | AG3: Prostheses/Implants/Devices | AH3: Radiotherapy | AI3: Secondary Commissioning Costs | AJ3: Specialist Procedure Suites excluding Endoscopy Units | AK3: Specialist Procedure Suite - Endoscopy Units Only | AL3: Specialist Nursing Staff | AM3: Therapies | AN3: Wards | AO3: Overheads
A4: GA03C | B4: Very Complex Open, Hepatobiliary or Pancreatic Procedures, with CC Score 4+ | C4: EL | D4: Elective | E4: 21 | F4: 263 | G4: 20 | H4: 235 | I4: 484.97872 | J4: 207 | K4: 187.96266 | L4: 9 | M4: 30.888889 | N4: 26412.925 | O4: 408.6282 | P4: 146.34924 | Q4: 5246.1964 | R4: 167.87278 | S4: 0.88908327 | T4: 739.55824 | U4: 3.8022814e-05 | V4: 103.12572 | W4: 364.49979 | X4: 5609.349 | Y4: 3720.9928 | Z4: 374.55288 | AA4: 1.254913 | AB4: 20.145112 | AC4: 1.3536378 | AD4: 204.15531 | AE4: 741.10315 | AF4: 189.19789 | AG4: 95.961089 | AH4: 0.090760456 | AI4: 4.3871803 | AJ4: 9.6342763 | AK4: 30.332621 | AL4: 41.905067 | AM4: 398.6938 | AN4: 3196.2732 | AO4: 4596.4231
A5: GA03C | B5: Very Complex Open, Hepatobiliary or Pancreatic Procedures, with CC Score 4+ | C5: NE | D5: Non Elective | E5: 43 | F5: 205 | G5: 18 | H5: 65 | I5: 352.95385 | J5: 74 | K5: 251.71514 | L5: 13 | M5: 216.30769 | N5: 14016.908 | O5: 164.39761 | P5: 133.04974 | Q5: 2113.9389 | R5: 156.57179 | S5: 0 | T5: 448.22653 | U5: 0.0295642 | V5: 123.4446 | W5: 392.25089 | X5: 2203.2943 | Y5: 965.33674 | Z5: 316.97091 | AA5: 0.9650486 | AB5: 13.515709 | AC5: 1.3750166 | AD5: 111.53576 | AE5: 440.71589 | AF5: 145.87284 | AG5: 52.077505 | AH5: 0.47141463 | AI5: 4.6271884 | AJ5: 4.6651326 | AK5: 27.689394 | AL5: 87.163242 | AM5: 239.16654 | AN5: 3117.7391 | AO5: 2751.8167
A6: GA03D | B6: Very Complex Open, Hepatobiliary or Pancreatic Procedures, with CC Score 2-3 | C6: EL | D6: Elective | E6: 17 | F6: 281 | G6: 11 | H6: 253 | I6: 442.11067 | J6: 202 | K6: 96.63736 | L6: 2 | M6: 47.5 | N6: 16344.688 | O6: 142.09422 | P6: 81.595274 | Q6: 2038.8175 | R6: 32.597441 | S6: 0 | T6: 346.45836 | U6: 0 | V6: 64.59473 | W6: 120.60584 | X6: 3823.5505 | Y6: 3619.2966 | Z6: 296.23054 | AA6: 0.052032832 | AB6: 23.822188 | AC6: 1.0439353 | AD6: 181.15812 | AE6: 320.69041 | AF6: 71.481806 | AG6: 66.008074 | AH6: 0.097224199 | AI6: 3.2872283 | AJ6: 8.5401129 | AK6: 12.506732 | AL6: 22.921924 | AM6: 178.34506 | AN6: 2093.0314 | AO6: 2795.86
A7: GA03D | B7: Very Complex Open, Hepatobiliary or Pancreatic Procedures, with CC Score 2-3 | C7: NE | D7: Non Elective | E7: 37 | F7: 106 | G7: 12 | H7: 41 | I7: 353.36585 | J7: 32 | K7: 274.9275 | L7: 3 | M7: 35 | N7: 9799.1523 | O7: 96.642076 | P7: 76.947597 | Q7: 749.85046 | R7: 38.329383 | S7: 0.89925397 | T7: 267.8431 | U7: 9.4415644e-05 | V7: 42.58925 | W7: 214.64079 | X7: 2210.7224 | Y7: 1211.4584 | Z7: 323.58764 | AA7: 0.2572282 | AB7: 14.19715 | AC7: 0.59682172 | AD7: 72.996019 | AE7: 210.97181 | AF7: 80.374907 | AG7: 20.967098 | AH7: 0.02509434 | AI7: 1.0463276 | AJ7: 1.0027661 | AK7: 12.043944 | AL7: 44.119618 | AM7: 129.33919 | AN7: 2101.4798 | AO7: 1876.2237
A8: GA03E | B8: Very Complex Open, Hepatobiliary or Pancreatic Procedures, with CC Score 0-1 | C8: EL | D8: Elective | E8: 29 | F8: 509 | G8: 8 | H8: 464 | I8: 442.59052 | J8: 305 | K8: 85.988383 | L8: 1 | M8: 100 | N8: 13681.545 | O8: 97.639898 | P8: 71.011729 | Q8: 1387.8919 | R8: 37.56109 | S8: 0.024768749 | T8: 252.95562 | U8: 0 | V8: 33.203217 | W8: 79.308136 | X8: 3221.6807 | Y8: 3689.0508 | Z8: 209.95645 | AA8: 0.082824906 | AB8: 11.057364 | AC8: 0.98582018 | AD8: 135.70701 | AE8: 302.02806 | AF8: 64.914053 | AG8: 77.778223 | AH8: 0.029449902 | AI8: 19.184561 | AJ8: 4.112869 | AK8: 11.520572 | AL8: 24.254636 | AM8: 140.13222 | AN8: 1597.1473 | AO8: 2212.3248
A9: GA03E | B9: Very Complex Open, Hepatobiliary or Pancreatic Procedures, with CC Score 0-1 | C9: NE | D9: Non Elective | E9: 39 | F9: 119 | G9: 10 | H9: 40 | I9: 284.925 | J9: 17 | K9: 51.298824 | L9: 3 | M9: 31.333333 | N9: 7802.4142 | O9: 50.231153 | P9: 59.814376 | Q9: 335.2498 | R9: 105.56768 | S9: 0.020840336 | T9: 337.52948 | U9: 0 | V9: 58.268466 | W9: 242.67684 | X9: 1464.2009 | Y9: 944.77209 | Z9: 201.61875 | AA9: 0.026312672 | AB9: 10.368773 | AC9: 1.198686 | AD9: 46.539381 | AE9: 169.15627 | AF9: 99.759984 | AG9: 12.046527 | AH9: 0.047142857 | AI9: 1.821862 | AJ9: 1.1843511 | AK9: 15.886177 | AL9: 41.933254 | AM9: 70.20383 | AN9: 2192.8722 | AO9: 1339.419
A10: GA03E | B10: Very Complex Open, Hepatobiliary or Pancreatic Procedures, with CC Score 0-1 | C10: DC | D10: Day Case | E10: 3 | F10: 3 | G10: 0 | H10: 1 | I10: 62 | J10: 0 | K10: NULL | L10: 1 | M10: 52 | N10: 2880.7509 | O10: 0.78666235 | P10: 7.0484608 | Q10: 0 | R10: 0 | S10: 0 | T10: 3.5265597 | U10: 0 | V10: 0 | W10: 0 | X10: 249.31969 | Y10: 171.74333 | Z10: 22.163554 | AA10: 0.0092912135 | AB10: 0.091658057 | AC10: 0 | AD10: 15.825008 | AE10: 15.907524 | AF10: 2.0243209 | AG10: 0.023539769 | AH10: 0 | AI10: 1996.2099 | AJ10: 0 | AK10: 242.59442 | AL10: 0 | AM10: 0.27021149 | AN10: 60.29 | AO10: 92.91679
A11: GA04C | B11: Complex Open, Hepatobiliary or Pancreatic Procedures, with CC Score 3+ | C11: EL | D11: Elective | E11: 19 | F11: 214 | G11: 14 | H11: 188 | I11: 382.48404 | J11: 152 | K11: 296.52833 | L11: 3 | M11: 263.33333 | N11: 20466.123 | O11: 252.91039 | P11: 93.697454 | Q11: 4193.6403 | R11: 85.62138 | S11: 0 | T11: 507.44614 | U11: 9.3457944e-05 | V11: 93.3782 | W11: 294.24264 | X11: 4084.4371 | Y11: 2844.8015 | Z11: 674.56977 | AA11: 0.67349364 | AB11: 22.002581 | AC11: 1.0286544 | AD11: 257.71138 | AE11: 572.94091 | AF11: 115.45218 | AG11: 97.556803 | AH11: 0.093271028 | AI11: 3.5472041 | AJ11: 10.639196 | AK11: 18.472707 | AL11: 23.019503 | AM11: 314.2097 | AN11: 2290.1083 | AO11: 3613.9227
A12: GA04C | B12: Complex Open, Hepatobiliary or Pancreatic Procedures, with CC Score 3+ | C12: NE | D12: Non Elective | E12: 16 | F12: 27 | G12: 36 | H12: 19 | I12: 360.26316 | J12: 15 | K12: 218.52067 | L12: 2 | M12: 31 | N12: 29737.539 | O12: 217.47033 | P12: 189.90961 | Q12: 5200.1125 | R12: 2942.0391 | S12: 0 | T12: 1722.2133 | U12: 0.00074074074 | V12: 95.801727 | W12: 413.62958 | X12: 4122.1615 | Y12: 1886.4815 | Z12: 2022.0138 | AA12: 1.6452939 | AB12: 16.821162 | AC12: 1.3964864 | AD12: 76.741698 | AE12: 763.97607 | AF12: 502.29355 | AG12: 106.92429 | AH12: 0 | AI12: 10.500461 | AJ12: 0.0015297063 | AK12: 43.737773 | AL12: 272.17945 | AM12: 212.67617 | AN12: 3581.4774 | AO12: 5335.3346
A13: GA04D | B13: Complex Open, Hepatobiliary or Pancreatic Procedures, with CC Score 0-2 | C13: EL | D13: Elective | E13: 26 | F13: 591 | G13: 6 | H13: 541 | I13: 312.12754 | J13: 391 | K13: 80.199454 | L13: 1 | M13: 100 | N13: 11708.381 | O13: 86.059271 | P13: 70.071583 | Q13: 1304.2739 | R13: 17.581193 | S13: 0 | T13: 219.0888 | U13: 0 | V13: 23.276515 | W13: 64.305217 | X13: 2871.8155 | Y13: 2600.6281 | Z13: 546.23111 | AA13: 0.15573755 | AB13: 13.814352 | AC13: 0.68612952 | AD13: 141.2277 | AE13: 231.57746 | AF13: 43.009219 | AG13: 82.838307 | AH13: 0.089847716 | AI13: 4.531224 | AJ13: 3.0719745 | AK13: 8.5682038 | AL13: 16.0366 | AM13: 81.113045 | AN13: 1240.5981 | AO13: 2037.7323
A14: GA04D | B14: Complex Open, Hepatobiliary or Pancreatic Procedures, with CC Score 0-2 | C14: NE | D14: Non Elective | E14: 9 | F14: 21 | G14: 17 | H14: 16 | I14: 309.875 | J14: 12 | K14: 90.166667 | L14: 1 | M14: 11 | N14: 20357.731 | O14: 116.82696 | P14: 64.25769 | Q14: 1649.3335 | R14: 139.5443 | S14: 0 | T14: 754.40556 | U14: 0 | V14: 52.644165 | W14: 120.16626 | X14: 3833.5182 | Y14: 1952.5916 | Z14: 1066.3934 | AA14: 0.0047783402 | AB14: 29.658825 | AC14: 0 | AD14: 324.62722 | AE14: 422.04469 | AF14: 228.23195 | AG14: 72.974166 | AH14: 0.035238095 | AI14: 1.4252134 | AJ14: 11.908155 | AK14: 34.656346 | AL14: 276.6597 | AM14: 112.52658 | AN14: 5279.9471 | AO14: 3813.3493
A15: GA04D | B15: Complex Open, Hepatobiliary or Pancreatic Procedures, with CC Score 0-2 | C15: DC | D15: Day Case | E15: 1 | F15: 1 | G15: 0 | H15: 0 | I15: NULL | J15: 0 | K15: NULL | L15: 1 | M15: 60 | N15: 1441.72 | O15: 2.86 | P15: 6.82 | Q15: 0 | R15: 0 | S15: 0 | T15: 191.51 | U15: 0 | V15: 6.71 | W15: 12.43 | X15: 263.45 | Y15: 0.77 | Z15: 169.4 | AA15: 2.53 | AB15: 4.29 | AC15: 0 | AD15: 0 | AE15: 0 | AF15: 0 | AG15: 0 | AH15: 0 | AI15: 0 | AJ15: 21.89 | AK15: 505.78 | AL15: 15.84 | AM15: 0.33 | AN15: 0.11 | AO15: 237
A16: GA05C | B16: Very Major Open, Hepatobiliary or Pancreatic Procedures, with CC Score 3+ | C16: EL | D16: Elective | E16: 41 | F16: 297 | G16: 9 | H16: 269 | I16: 300.28253 | J16: 172 | K16: 139.87203 | L16: 4 | M16: 39 | N16: 12596.686 | O16: 154.82169 | P16: 82.076366 | Q16: 2016.5164 | R16: 196.23271 | S16: 5.764498 | T16: 320.18125 | U16: 0.056781916 | V16: 32.087081 | W16: 203.05758 | X16: 2695.6935 | Y16: 2109.1277 | Z16: 276.9202 | AA16: 0.95282217 | AB16: 6.3162832 | AC16: 1.5228629 | AD16: 80.278025 | AE16: 346.22848 | AF16: 130.87718 | AG16: 43.299331 | AH16: 0.032188552 | AI16: 2.5611169 | AJ16: 13.107599 | AK16: 20.335356 | AL16: 27.967075 | AM16: 155.06755 | AN16: 1674.0783 | AO16: 2001.5265
A17: GA05C | B17: Very Major Open, Hepatobiliary or Pancreatic Procedures, with CC Score 3+ | C17: NE | D17: Non Elective | E17: 29 | F17: 92 | G17: 15 | H17: 67 | I17: 235.10448 | J17: 34 | K17: 3636.0309 | L17: 15 | M17: 93 | N17: 14659.821 | O17: 317.77467 | P17: 115.79304 | Q17: 3300.1132 | R17: 96.1509 | S17: 0.0045652174 | T17: 352.10338 | U17: 3.236218e-05 | V17: 60.657754 | W17: 391.80034 | X17: 2558.0137 | Y17: 1465.3912 | Z17: 227.45675 | AA17: 0.91580735 | AB17: 4.2497731 | AC17: 0.48695401 | AD17: 53.24544 | AE17: 301.1918 | AF17: 158.87825 | AG17: 119.95658 | AH17: 0.028152174 | AI17: 1.9995165 | AJ17: 3.2119603 | AK17: 116.30575 | AL17: 45.428143 | AM17: 162.9699 | AN17: 2290.151 | AO17: 2515.5427
A18: GA05C | B18: Very Major Open, Hepatobiliary or Pancreatic Procedures, with CC Score 3+ | C18: DC | D18: Day Case | E18: 2 | F18: 2 | G18: 0 | H18: 0 | I18: NULL | J18: 0 | K18: NULL | L18: 1 | M18: 60 | N18: 768.99002 | O18: 1.43 | P18: 5.0285512 | Q18: 0 | R18: 0 | S18: 0 | T18: 95.755 | U18: 0 | V18: 3.465 | W18: 6.4056695 | X18: 91.465 | Y18: 0.385 | Z18: 84.7 | AA18: 1.32 | AB18: 2.2 | AC18: 4.5727324 | AD18: 0 | AE18: 25.23928 | AF18: 0 | AG18: 0 | AH18: 0 | AI18: 0 | AJ18: 5.28 | AK18: 270.01389 | AL18: 9.7998363 | AM18: 15.666976 | AN18: 8.4578583 | AO18: 137.80522
A19: GA05D | B19: Very Major Open, Hepatobiliary or Pancreatic Procedures, with CC Score 0-2 | C19: EL | D19: Elective | E19: 47 | F19: 946 | G19: 5 | H19: 871 | I19: 261.62342 | J19: 515 | K19: 79.978628 | L19: 10 | M19: 93.4 | N19: 8980.8855 | O19: 68.566985 | P19: 78.23927 | Q19: 882.5396 | R19: 15.407052 | S19: 0.0024689752 | T19: 173.37822 | U19: 0.018448653 | V19: 15.694655 | W19: 46.475665 | X19: 2239.989 | Y19: 2154.3192 | Z19: 173.47733 | AA19: 0.32974091 | AB19: 4.8693023 | AC19: 0.88125099 | AD19: 70.932487 | AE19: 204.67458 | AF19: 44.65626 | AG19: 46.681518 | AH19: 0.02320296 | AI19: 28.242941 | AJ19: 4.2569816 | AK19: 13.16238 | AL19: 18.112527 | AM19: 104.52412 | AN19: 1022.5415 | AO19: 1568.8888
A20: GA05D | B20: Very Major Open, Hepatobiliary or Pancreatic Procedures, with CC Score 0-2 | C20: NE | D20: Non Elective | E20: 28 | F20: 102 | G20: 6 | H20: 66 | I20: 222.25758 | J20: 25 | K20: 290.03 | L20: 4 | M20: 242 | N20: 7700.4593 | O20: 76.962842 | P20: 74.590648 | Q20: 853.39545 | R20: 47.531562 | S20: 0 | T20: 181.20963 | U20: 0.034961874 | V20: 45.282653 | W20: 115.03941 | X20: 1654.0529 | Y20: 1349.2874 | Z20: 156.43685 | AA20: 0.72622083 | AB20: 5.5729184 | AC20: 0.54687477 | AD20: 41.941856 | AE20: 155.50581 | AF20: 60.440765 | AG20: 39.328825 | AH20: 0.020686275 | AI20: 1.0316876 | AJ20: 0.0058773934 | AK20: 22.159821 | AL20: 16.097304 | AM20: 69.81889 | AN20: 1419.9444 | AO20: 1313.493
A21: GA05D | B21: Very Major Open, Hepatobiliary or Pancreatic Procedures, with CC Score 0-2 | C21: DC | D21: Day Case | E21: 14 | F21: 40 | G21: 0 | H21: 3 | I21: 184.33333 | J21: 1 | K21: 44 | L21: 17 | M21: 32.823529 | N21: 905.68453 | O21: 16.348858 | P21: 7.9116308 | Q21: 47.52241 | R21: 0.20072254 | S21: 0 | T21: 21.329682 | U21: 0 | V21: 0.34684959 | W21: 53.032419 | X21: 186.99009 | Y21: 86.635612 | Z21: 47.310386 | AA21: 0.76024578 | AB21: 0.25574613 | AC21: 0.73275013 | AD21: 3.7580186 | AE21: 14.733699 | AF21: 1.8032159 | AG21: 6.1615318 | AH21: 0 | AI21: 0.064983425 | AJ21: 51.121005 | AK21: 191.46147 | AL21: 4.8455252 | AM21: 4.2792681 | AN21: 26.727696 | AO21: 131.3509
A22: GA06C | B22: Major Open, Hepatobiliary or Pancreatic Procedures, with CC Score 2+ | C22: EL | D22: Elective | E22: 41 | F22: 164 | G22: 7 | H22: 139 | I22: 228.01439 | J22: 57 | K22: 152.64287 | L22: 11 | M22: 53.454545 | N22: 9406.5086 | O22: 71.632652 | P22: 84.681958 | Q22: 1106.7146 | R22: 29.683311 | S22: 0.0071341463 | T22: 184.76671 | U22: 0 | V22: 42.488044 | W22: 134.80646 | X22: 2091.1432 | Y22: 1656.6736 | Z22: 251.41226 | AA22: 0.20031773 | AB22: 8.923245 | AC22: 0.61990311 | AD22: 64.749887 | AE22: 224.26505 | AF22: 55.204331 | AG22: 53.434578 | AH22: 0.045914634 | AI22: 2.4256941 | AJ22: 6.9384631 | AK22: 58.271476 | AL22: 37.076936 | AM22: 121.97293 | AN22: 1288.0907 | AO22: 1830.279
A23: GA06C | B23: Major Open, Hepatobiliary or Pancreatic Procedures, with CC Score 2+ | C23: NE | D23: Non Elective | E23: 39 | F23: 101 | G23: 12 | H23: 57 | I23: 189.45614 | J23: 28 | K23: 159.75381 | L23: 15 | M23: 99 | N23: 11436.163 | O23: 243.17798 | P23: 121.77192 | Q23: 2019.4818 | R23: 151.60122 | S23: 0.0053465347 | T23: 266.30853 | U23: 4.5166693 | V23: 105.76653 | W23: 337.07284 | X23: 1739.0506 | Y23: 943.22566 | Z23: 228.8546 | AA23: 0.4425083 | AB23: 11.506597 | AC23: 0.44847532 | AD23: 99.25853 | AE23: 258.87234 | AF23: 98.593679 | AG23: 39.123223 | AH23: 0.045940594 | AI23: 2.5018776 | AJ23: 11.622867 | AK23: 111.04733 | AL23: 76.818108 | AM23: 131.17661 | AN23: 2319.7897 | AO23: 2114.0812
A24: GA06C | B24: Major Open, Hepatobiliary or Pancreatic Procedures, with CC Score 2+ | C24: DC | D24: Day Case | E24: 11 | F24: 18 | G24: 0 | H24: 1 | I24: 85 | J24: 0 | K24: NULL | L24: 10 | M24: 124 | N24: 1152.267 | O24: 0.54444444 | P24: 12.521446 | Q24: 0.26802884 | R24: 0.0054212142 | S24: 0 | T24: 31.2802 | U24: 0 | V24: 22.21439 | W24: 53.5082 | X24: 96.002009 | Y24: 90.296432 | Z24: 32.450408 | AA24: 0.048888889 | AB24: 0.079444444 | AC24: 0.27471079 | AD24: 10.559644 | AE24: 35.292055 | AF24: 2.3849681 | AG24: 3.8990912 | AH24: 0 | AI24: 313.24395 | AJ24: 137.27353 | AK24: 142.61996 | AL24: 9.1213521 | AM24: 1.4290525 | AN24: 42.191142 | AO24: 114.75821
A25: GA06D | B25: Major Open, Hepatobiliary or Pancreatic Procedures, with CC Score 0-1 | C25: EL | D25: Elective | E25: 43 | F25: 257 | G25: 4 | H25: 188 | I25: 206.41489 | J25: 48 | K25: 67.15625 | L25: 31 | M25: 142.41935 | N25: 6037.0314 | O25: 22.955234 | P25: 50.567279 | Q25: 372.25337 | R25: 13.411236 | S25: 0.15972677 | T25: 104.82347 | U25: 0.21708799 | V25: 33.413164 | W25: 71.414463 | X25: 1383.1885 | Y25: 1215.6998 | Z25: 148.32324 | AA25: 0.14662717 | AB25: 9.5749428 | AC25: 1.0245894 | AD25: 54.479588 | AE25: 123.56294 | AF25: 36.04782 | AG25: 20.808405 | AH25: 1.2389546 | AI25: 3.1942769 | AJ25: 6.1872208 | AK25: 101.05997 | AL25: 30.203219 | AM25: 47.131667 | AN25: 1012.4232 | AO25: 1173.5214
A26: GA06D | B26: Major Open, Hepatobiliary or Pancreatic Procedures, with CC Score 0-1 | C26: NE | D26: Non Elective | E26: 29 | F26: 67 | G26: 7 | H26: 43 | I26: 178.90698 | J26: 10 | K26: 628.15 | L26: 8 | M26: 133.625 | N26: 6709.2616 | O26: 89.794067 | P26: 105.91698 | Q26: 224.71342 | R26: 5.4878736 | S26: 0.0074626866 | T26: 180.24906 | U26: 0.00048656716 | V26: 36.630323 | W26: 165.73178 | X26: 1393.8168 | Y26: 1204.5279 | Z26: 168.25578 | AA26: 0.79572862 | AB26: 8.5045356 | AC26: 0.39207555 | AD26: 24.672009 | AE26: 163.95808 | AF26: 39.869616 | AG26: 37.765528 | AH26: 0 | AI26: 0.3048073 | AJ26: 22.094411 | AK26: 98.325104 | AL26: 68.540636 | AM26: 60.475585 | AN26: 1524.8572 | AO26: 1083.5751
A27: GA06D | B27: Major Open, Hepatobiliary or Pancreatic Procedures, with CC Score 0-1 | C27: DC | D27: Day Case | E27: 34 | F27: 95 | G27: 0 | H27: 11 | I27: 98.909091 | J27: 0 | K27: NULL | L27: 28 | M27: 74.857143 | N27: 918.85599 | O27: 5.2809731 | P27: 7.1361628 | Q27: 0.030210526 | R27: 1.5662216 | S27: 1.454 | T27: 8.7121371 | U27: 0 | V27: 5.3653789 | W27: 59.094943 | X27: 121.63439 | Y27: 98.364366 | Z27: 25.176715 | AA27: 0.026924986 | AB27: 0.25006732 | AC27: 0.204426 | AD27: 14.184406 | AE27: 45.866688 | AF27: 2.042619 | AG27: 1.9246414 | AH27: 0 | AI27: 0.067069104 | AJ27: 127.64224 | AK27: 185.12646 | AL27: 5.0678987 | AM27: 4.1931283 | AN27: 27.595363 | AO27: 170.84922
A28: GA07C | B28: Intermediate Open, Hepatobiliary or Pancreatic Procedures, with CC Score 3+ | C28: EL | D28: Elective | E28: 52 | F28: 175 | G28: 6 | H28: 134 | I28: 189.70896 | J28: 42 | K28: 73.334845 | L28: 10 | M28: 198.5 | N28: 7072.1235 | O28: 169.43342 | P28: 65.000969 | Q28: 576.40552 | R28: 54.590488 | S28: 0.019535343 | T28: 133.0432 | U28: 0.12070039 | V28: 32.116938 | W28: 84.273432 | X28: 1555.9386 | Y28: 1347.6842 | Z28: 130.68884 | AA28: 0.96329895 | AB28: 2.7287769 | AC28: 2.2853389 | AD28: 47.59261 | AE28: 221.30019 | AF28: 59.568446 | AG28: 44.474796 | AH28: 0.0071428571 | AI28: 2.2550736 | AJ28: 5.7247133 | AK28: 46.351101 | AL28: 48.124549 | AM28: 79.94356 | AN28: 1190.4974 | AO28: 1170.9903
A29: GA07C | B29: Intermediate Open, Hepatobiliary or Pancreatic Procedures, with CC Score 3+ | C29: NE | D29: Non Elective | E29: 51 | F29: 185 | G29: 10 | H29: 109 | I29: 203.40367 | J29: 46 | K29: 329.53543 | L29: 15 | M29: 76.412667 | N29: 10177.356 | O29: 140.17484 | P29: 95.254676 | Q29: 2023.9549 | R29: 38.601854 | S29: 7.0069081 | T29: 213.95115 | U29: 0.7491939 | V29: 47.932219 | W29: 209.19815 | X29: 1794.206 | Y29: 1054.0281 | Z29: 183.92714 | AA29: 3.4510136 | AB29: 19.624781 | AC29: 0.77872566 | AD29: 41.191453 | AE29: 281.10819 | AF29: 87.332305 | AG29: 30.644073 | AH29: 3.223123 | AI29: 1.3021829 | AJ29: 0.15304631 | AK29: 71.347474 | AL29: 65.0172 | AM29: 147.91239 | AN29: 1775.5983 | AO29: 1839.6864
A30: GA07C | B30: Intermediate Open, Hepatobiliary or Pancreatic Procedures, with CC Score 3+ | C30: DC | D30: Day Case | E30: 8 | F30: 11 | G30: 0 | H30: 4 | I30: 105.75 | J30: 0 | K30: NULL | L30: 2 | M30: 60.5 | N30: 1573.0837 | O30: 0.37420667 | P30: 10.059651 | Q30: 0 | R30: 0.055727273 | S30: 0 | T30: 12.178144 | U30: 0 | V30: 45.03 | W30: 276.73394 | X30: 420.60296 | Y30: 360.42775 | Z30: 21.861817 | AA30: 2.2893263 | AB30: 0 | AC30: 1.6287822 | AD30: 0.41909091 | AE30: 19.579809 | AF30: 1.5592727 | AG30: 7.4804629 | AH30: 0 | AI30: 0 | AJ30: 0 | AK30: 48.705814 | AL30: 4.5373016 | AM30: 14.501896 | AN30: 88.769105 | AO30: 236.28776
A31: GA07D | B31: Intermediate Open, Hepatobiliary or Pancreatic Procedures, with CC Score 1-2 | C31: EL | D31: Elective | E31: 58 | F31: 389 | G31: 4 | H31: 318 | I31: 182.0283 | J31: 65 | K31: 81.035179 | L31: 22 | M31: 82.681818 | N31: 5937.5509 | O31: 55.526076 | P31: 46.820393 | Q31: 313.89705 | R31: 11.672889 | S31: 27.920202 | T31: 102.77624 | U31: 0.00076287407 | V31: 13.769816 | W31: 51.872352 | X31: 1548.1755 | Y31: 1373.6219 | Z31: 110.90655 | AA31: 0.15955444 | AB31: 4.2755652 | AC31: 1.624956 | AD31: 47.777185 | AE31: 105.9253 | AF31: 35.443554 | AG31: 60.619952 | AH31: 0.0075321337 | AI31: 2.0449479 | AJ31: 2.6385983 | AK31: 47.640134 | AL31: 33.307555 | AM31: 42.381724 | AN31: 837.4811 | AO31: 1059.2634
A32: GA07D | B32: Intermediate Open, Hepatobiliary or Pancreatic Procedures, with CC Score 1-2 | C32: NE | D32: Non Elective | E32: 49 | F32: 166 | G32: 6 | H32: 122 | I32: 161.70492 | J32: 26 | K32: 183.08282 | L32: 12 | M32: 112 | N32: 5647.4061 | O32: 83.283154 | P32: 76.50506 | Q32: 353.33892 | R32: 9.5472652 | S32: 7.2193151 | T32: 112.74086 | U32: 3.5813662 | V32: 28.754281 | W32: 126.37242 | X32: 1249.9546 | Y32: 1104.1582 | Z32: 74.434111 | AA32: 0.34467144 | AB32: 2.0792542 | AC32: 0.47610894 | AD32: 30.695231 | AE32: 151.44697 | AF32: 48.78702 | AG32: 11.111514 | AH32: 0.043335467 | AI32: 1.6917703 | AJ32: 0.020641448 | AK32: 51.039039 | AL32: 22.368631 | AM32: 45.12293 | AN32: 1052.2349 | AO32: 1000.0543
A33: GA07D | B33: Intermediate Open, Hepatobiliary or Pancreatic Procedures, with CC Score 1-2 | C33: DC | D33: Day Case | E33: 29 | F33: 50 | G33: 0 | H33: 16 | I33: 103 | J33: 0 | K33: NULL | L33: 9 | M33: 198.29778 | N33: 1264.8589 | O33: 3.523176 | P33: 12.092652 | Q33: 0 | R33: 0.09382652 | S33: 0.080196646 | T33: 15.695775 | U33: 0 | V33: 17.066223 | W33: 30.53715 | X33: 307.01303 | Y33: 349.77723 | Z33: 27.420456 | AA33: 0.5316158 | AB33: 2.2424538 | AC33: 0.88728128 | AD33: 12.120392 | AE33: 19.970432 | AF33: 4.3351557 | AG33: 17.453595 | AH33: 0.0124 | AI33: 0.92752602 | AJ33: 0.78084766 | AK33: 164.30082 | AL33: 8.6303835 | AM33: 7.7639787 | AN33: 58.351128 | AO33: 203.25122
A34: GA07E | B34: Intermediate Open, Hepatobiliary or Pancreatic Procedures, with CC Score 0 | C34: EL | D34: Elective | E34: 58 | F34: 478 | G34: 2 | H34: 408 | I34: 162.02451 | J34: 59 | K34: 201.38904 | L34: 14 | M34: 132.42857 | N34: 4853.7939 | O34: 32.275576 | P34: 53.002585 | Q34: 184.97927 | R34: 16.103281 | S34: 2.3175656 | T34: 74.462774 | U34: 0.030750909 | V34: 7.1017264 | W34: 25.910717 | X34: 1243.947 | Y34: 1289.3657 | Z34: 89.562707 | AA34: 0.07178891 | AB34: 3.2052517 | AC34: 1.1768453 | AD34: 35.721261 | AE34: 88.947819 | AF34: 27.968774 | AG34: 25.126027 | AH34: 0.013054393 | AI34: 47.860315 | AJ34: 1.9439991 | AK34: 22.381805 | AL34: 32.282624 | AM34: 23.051467 | AN34: 634.55587 | AO34: 890.42744
A35: GA07E | B35: Intermediate Open, Hepatobiliary or Pancreatic Procedures, with CC Score 0 | C35: NE | D35: Non Elective | E35: 46 | F35: 153 | G35: 5 | H35: 106 | I35: 160.4434 | J35: 11 | K35: 303.74727 | L35: 11 | M35: 175.18182 | N35: 4843.2021 | O35: 53.536547 | P35: 59.403502 | Q35: 159.29 | R35: 7.9896162 | S35: 0.075521583 | T35: 74.567078 | U35: 0.045716626 | V35: 22.706911 | W35: 135.99259 | X35: 1018.265 | Y35: 1018.3512 | Z35: 65.684552 | AA35: 0.35030104 | AB35: 1.4107052 | AC35: 0.29868412 | AD35: 22.544485 | AE35: 95.552714 | AF35: 37.151799 | AG35: 22.524697 | AH35: 0.053594771 | AI35: 1.859019 | AJ35: 3.3086045 | AK35: 33.222149 | AL35: 31.512937 | AM35: 52.427576 | AN35: 1029.3114 | AO35: 895.76539
