Workbook

Sheet Model
B1: Model Structure | D1: All the key assumptions and results are are on the control panel.
D2: Changing an assumption on the control panel will change the results on the individual worksheets.
D3: To change a key assumption, change it on the control panel not on the individual worksheets
B5: Control panel | D5: Sales | F5: Cost of goods | H5: Operating costs | J5: Project Financials | L5: Lee vs Lor | N5: Licensor financial status
J6: For total project calculates | L6: For Licensee and Licensor calculates | N6: For Licensor only calculates
B7: Sales forecast
B8: Market share volume | D8: Calculates sales | J8: Sales | L8: Sales
B9: Price premium
B10: Share of voice
B12: Cost of goods - who manufactures? | F12: Calculates cost of goods | J12: Cost of goods | L12: Cost of goods
B13: Licensor manufacture | F13: in each scenario
B14: Zero capital spend
B15: Profit mark-up on cost
B16: Licensee manufacture
B17: Capital spend
B18: Lower cost of goods
B20: R & D costs - who pays? | H20: Calculates R & D costs | J20: R&D costs | L20: R&D costs
B21: Formulation and scale up
B22: Clinical trials
B25: Sales and marketing | H25: Calculates S & P costs | J25: S&P and other costs | L25: S&P and other costs
B26: Salesforce cost allocation | H26: and other costs
B27: Direct promotion costs | H27: distribution, admin, etc
B29: Licence fees and royalty | L29: Deal payments | N29: Lor year end cash balance
B30: Signature fee
B31: Milestone payments
B32: Royalty
J34: Calculates Project NPV and IRR | L34: Calculates Lee and Lor NPV and IRR
B36: NPV summary for Lee and Lor

Sheet Control
B2: CONTROL PANEL | F2: Key assumptions shown in red in yellow cells. Changes to these cells with change the results of the model | S2: Results are shown in blue | Y2: 2008
B4: SALES FORECAST | M4: 0 | N4: =M4+1 -> 1 | O4: 2 | P4: =O4+1 -> 3 | Q4: =P4+1 -> 4 | R4: =Q4+1 -> 5 | S4: =R4+1 -> 6 | T4: =S4+1 -> 7 | U4: =T4+1 -> 8 | V4: =U4+1 -> 9 | W4: =V4+1 -> 10 | ... Y4: =X4+1 -> 12
C5: Number of competing products (incl. prolutamide) Enter 2 or 3 | I5: 2 | K5: Yr 5 Mkt Sh | L5: Sales $m | M5: =Y2+1 -> 2009 | N5: =M5+1 -> 2010 | O5: =N5+1 -> 2011 | P5: =O5+1 -> 2012 | Q5: =P5+1 -> 2013 | R5: =Q5+1 -> 2014 | S5: =R5+1 -> 2015 | T5: =S5+1 -> 2016 | U5: =T5+1 -> 2017 | ... Y5: =X5+1 -> 2021
C6: Prolutamide TTP advantage versus Janssen product? YES = 1, NO= 0 | I6: 1 | K6: =Sales!G27 -> 0.38333333 | L6: US | P6: =Sales!J38 -> 71.165835 | Q6: =Sales!K38 -> 390.65902 | R6: =Sales!L38 -> 676.77395 | S6: =Sales!M38 -> 1145.6168 | T6: =Sales!N38 -> 1475.4927 | U6: =Sales!O38 -> 1785.3692 | V6: =Sales!P38 -> 2127.5686 | W6: =Sales!Q38 -> 2404.2916 | ... Y6: =Sales!S38 -> 2901.8369
C7: Price at parity / below / above: target price Enter: 0%,-30%,30% | H7: US | I7: 0 | K7: =Sales!G28 -> 0.40333333 | L7: Non US | P7: =Sales!J39 -> 0 | Q7: =Sales!K39 -> 53.555488 | R7: =Sales!L39 -> 363.58601 | S7: =Sales!M39 -> 713.74853 | T7: =Sales!N39 -> 1015.2856 | U7: =Sales!O39 -> 1280.1789 | V7: =Sales!P39 -> 1507.7218 | W7: =Sales!Q39 -> 1733.2251 | ... Y7: =Sales!S39 -> 2070.6781
C8: Price at parity / below / above: target price Enter: 0%,-30%,30% | H8: Non-US | I8: 0 | L8: Total | P8: =P6+P7 -> 71.165835 | Q8: =Q6+Q7 -> 444.21451 | R8: =R6+R7 -> 1040.36 | S8: =S6+S7 -> 1859.3653 | T8: =T6+T7 -> 2490.7782 | U8: =U6+U7 -> 3065.548 | V8: =V6+V7 -> 3635.2904 | W8: =W6+W7 -> 4137.5167 | ... Y8: =Y6+Y7 -> 4972.515
B9: COST OF GOODS | O9: R&D
C10: Will the Licensee manufacture inhouse? Enter 1 for YES or 0 for NO | I10: 0 | L10: NPV of savings to Licensee | N10: =COG!J70 -> 0 | U10: Additional patients for bicalutamide studies? Enter 1 for YES or 0 for NO | V10: 0
C11: If YES, capital expenditure by Licensee? Enter 15 for $15m or 30 for $30m | I11: 30 | L11: Licensee COG + plus royalty in | M11: 2021 | N11: ='Lee & Lor'!Q61 -> 0.1922494
C12: If NO, profit mark-up % applied by Licensor on cost of supply from CMO | I12: 0.25 | O12: IP COSTS | S12: US | T12: Non-US
B13: SALES AND MARKETING COSTS | I13: Yr 1-5 | J13: Yr 6-10 | L13: Full time | M13: 1st detail | O13: Royalties payable by Licensor to University | S13: 0.04 | T13: 0.04
C14: % time Licensee salesforce promote prolutamide | H14: US | I14: 1 | J14: 1 | L14: 1 | M14: 0.65
C15: % time Licensee salesforce promote prolutamide | H15: Non-US | I15: 1 | J15: 1 | L15: 1 | M15: 0.65
C16: US co-commercialisation profit share to Licensor Enter % | H16: US | I16: 0.5
C17: If US co-commercialisation enter fee per call paid to Licensor | H17: US | I17: 500 | R17: Net gain/(loss) to Licensee of co-commercialisation (= (gain)/loss to Licensor) NPV $m | S17: ='S&M'!G88 -> 432.36993
B19: ELEMENTS OF LICENSING DEAL | G19: Headline value excluding R&D and royalties | L19: =L22+R31+L36 -> 800 | M19: =L19/Y8 -> 0.16088438 | N19: % of peak sales
C20: R & D costs
D21: Licensee share of R&D costs | F21: % Lee pays | G21: Cost $m | I21: Other Financial Deal Terms | L21: $m
D22: Manufacturing scale-up | F22: 0.5 | G22: 48 | I22: Signature fee | L22: 150 | M22: =M5 -> 2009
D23: Phase 3 studies | F23: 1 | G23: ='R&D'!V20 -> 753.13338 | L23: Post chemo CRPC | N23: HSPC | P23: Non chemo CRPC | R23: Total
D24: Phase 4 studies | F24: 1 | G24: ='R&D'!V21 -> 69.981392 | I24: First patient dosed in clinical | L24: 0 | N24: 25 | O24: 2014 | P24: 25 | Q24: 2010 | R24: =L24+N24+P24 -> 50
D25: Non prostate cancer studies | F25: 0.5 | G25: ='R&D'!V28 -> 30.58856 | I25: Acceptance of filing | K25: US | L25: 10 | M25: 2010 | N25: 25 | O25: 2014 | P25: 10 | Q25: 2012 | R25: =L25+N25+P25 -> 45
E26: Total cost | G26: =SUM(G22:G25) -> 901.70333 | K26: Europe | L26: 5 | M26: 2014 | N26: 20 | O26: 2014 | P26: 5 | Q26: 2012 | R26: =L26+N26+P26 -> 30
D27: Cost to Licensee $m | G27: ='R&D'!E37 -> 862.40905 | K27: Japan | L27: 5 | M27: 2014 | N27: 10 | O27: 2014 | P27: 5 | Q27: 2013 | R27: =L27+N27+P27 -> 20
D28: Cost to Licensor $m | G28: ='R&D'!E38 -> 39.29428 | I28: Approval of MA | K28: US | L28: 40 | M28: 2014 | N28: 65 | O28: 2014 | P28: 40 | Q28: 2012 | R28: =L28+N28+P28 -> 145
K29: Europe | L29: 15 | M29: 2014 | N29: 30 | O29: 2014 | P29: 15 | Q29: 2013 | R29: =L29+N29+P29 -> 60
K30: Japan | L30: 15 | M30: 2014 | N30: 20 | O30: 2014 | P30: 15 | R30: =L30+N30+P30 -> 50
C31: Royalty payment by Licensee to Lor | K31: Total | L31: =SUM(L24:L30) -> 90 | N31: =SUM(N24:N30) -> 195 | P31: =SUM(P24:P30) -> 115 | R31: =L31+N31+P31 -> 400
E32: Sales < x | F32: 400 | G32: 0.1 | I32: Annual sales > $m | K32: 400 | L32: 25
E33: Sales > x < y | F33: 800 | G33: 0.12 | I33: Annual sales > $m | K33: 800 | L33: 50
C34: ` | E34: Sales > y > z | F34: 1200 | G34: 0.14 | I34: Annual sales > $m | K34: 1200 | L34: 75
E35: Sales > z | F35: 1600 | G35: 0.16 | I35: Annual sales > $m | K35: 1600 | L35: 100
L36: =SUM(L32:L35) -> 250
L37: Total | M37: =Y2+1 -> 2009 | N37: =M37+1 -> 2010 | O37: =N37+1 -> 2011 | P37: =O37+1 -> 2012 | Q37: =P37+1 -> 2013 | R37: =Q37+1 -> 2014 | S37: =R37+1 -> 2015 | T37: =S37+1 -> 2016 | U37: =T37+1 -> 2017 | ... Y37: =X37+1 -> 2021
J38: Total development milestones and upfront | L38: =SUM(M38:Y38) -> 535 | M38: =L22 -> 150 | N38: =L25+P24 -> 35 | P38: =P25+P26+P28 -> 55 | Q38: =P27+P29 -> 20 | R38: =N31+L31-L25 -> 275
J39: Total sales milestones | L39: =SUM(M39:Y39) -> 250 | M39: =IF(AND(M$8>=$K32,L$8<$K32),$L32,0)+IF(AND(M$8>=$K33,L$8<$K33),$L33,0)+IF(AND(M$8>=$K34,L$8<$K34),$L34,0)+IF(AND(M$8>=$K35,L$8<$K35),$L35,0) -> 0 | N39: =IF(AND(N$8>=$K32,M$8<$K32),$L32,0)+IF(AND(N$8>=$K33,M$8<$K33),$L33,0)+IF(AND(N$8>=$K34,M$8<$K34),$L34,0)+IF(AND(N$8>=$K35,M$8<$K35),$L35,0) -> 0 | O39: =IF(AND(O$8>=$K32,N$8<$K32),$L32,0)+IF(AND(O$8>=$K33,N$8<$K33),$L33,0)+IF(AND(O$8>=$K34,N$8<$K34),$L34,0)+IF(AND(O$8>=$K35,N$8<$K35),$L35,0) -> 0 | P39: =IF(AND(P$8>=$K32,O$8<$K32),$L32,0)+IF(AND(P$8>=$K33,O$8<$K33),$L33,0)+IF(AND(P$8>=$K34,O$8<$K34),$L34,0)+IF(AND(P$8>=$K35,O$8<$K35),$L35,0) -> 0 | Q39: =IF(AND(Q$8>=$K32,P$8<$K32),$L32,0)+IF(AND(Q$8>=$K33,P$8<$K33),$L33,0)+IF(AND(Q$8>=$K34,P$8<$K34),$L34,0)+IF(AND(Q$8>=$K35,P$8<$K35),$L35,0) -> 25 | R39: =IF(AND(R$8>=$K32,Q$8<$K32),$L32,0)+IF(AND(R$8>=$K33,Q$8<$K33),$L33,0)+IF(AND(R$8>=$K34,Q$8<$K34),$L34,0)+IF(AND(R$8>=$K35,Q$8<$K35),$L35,0) -> 50 | S39: =IF(AND(S$8>=$K32,R$8<$K32),$L32,0)+IF(AND(S$8>=$K33,R$8<$K33),$L33,0)+IF(AND(S$8>=$K34,R$8<$K34),$L34,0)+IF(AND(S$8>=$K35,R$8<$K35),$L35,0) -> 175 | T39: =IF(AND(T$8>=$K32,S$8<$K32),$L32,0)+IF(AND(T$8>=$K33,S$8<$K33),$L33,0)+IF(AND(T$8>=$K34,S$8<$K34),$L34,0)+IF(AND(T$8>=$K35,S$8<$K35),$L35,0) -> 0 | ... Y39: =IF(AND(Y$8>=$K32,X$8<$K32),$L32,0)+IF(AND(Y$8>=$K33,X$8<$K33),$L33,0)+IF(AND(Y$8>=$K34,X$8<$K34),$L34,0)+IF(AND(Y$8>=$K35,X$8<$K35),$L35,0) -> 0
I40: Total Lee milestone payments | L40: =L38+L39 -> 785 | M40: =M38+M39 -> 150 | N40: =N38+N39 -> 35 | O40: =O38+O39 -> 0 | P40: =P38+P39 -> 55 | Q40: =Q38+Q39 -> 45 | R40: =R38+R39 -> 325 | S40: =S38+S39 -> 175 | ... Y40: =Y38+Y39 -> 0
C41: Royalty payments assumed to stop at patent expiry | I41: Total Lee royalty payments | L41: =SUM(M41:W41) -> 2044.2325 | P41: ='Lee & Lor'!H71 -> 7.1165835 | Q41: ='Lee & Lor'!I71 -> 45.305741 | R41: ='Lee & Lor'!J71 -> 121.65039 | S41: ='Lee & Lor'!K71 -> 185.49845 | T41: ='Lee & Lor'!L71 -> 286.52452 | U41: ='Lee & Lor'!M71 -> 378.48769 | V41: ='Lee & Lor'!N71 -> 469.64646 | W41: ='Lee & Lor'!O71 -> 550.00267 | ... Y41: ='Lee & Lor'!Q71 -> 683.6024
C42: Duration of licence to Licensee | L42: =L41/SUM(Q8:V8) -> 0.16307473 | O42: Average royalty rate | P42: =P41/P8 -> 0.1 | Q42: =Q41/Q8 -> 0.10199068 | R42: =R41/R8 -> 0.11693106 | S42: =S41/S8 -> 0.099764393 | T42: =T41/T8 -> 0.11503413 | U42: =U41/U8 -> 0.12346493 | V42: =V41/V8 -> 0.12919091 | W42: =W41/W8 -> 0.13293062 | ... Y42: =Y41/Y8 -> 0.13747619
D43: Licence terminates: expiry data exclusivity / 10 years from launch whichever later | K43: Licensor gets terminal value (enter 0)
...

Sheet Sales
A1: SALES FORECAST | C1: Assumptions in yellow box from control panel | AL1: Working calculations and notes in grey
B2: Assumptions in red | J2: 1 | K2: 2 | L2: 3 | M2: 4 | N2: 5 | O2: 6 | P2: 7 | Q2: 8 | R2: 9 | S2: 10 | T2: =S2+1 -> 11 | U2: =T2+1 -> 12 | V2: =U2+1 -> 13 | W2: =V2+1 -> 14 | X2: =W2+1 -> 15 | Y2: =X2+1 -> 16 | AA2: Source
B3: Sales forecast | C3: 2005 | D3: 2006 | E3: 2007 | F3: 2008 | G3: 2009 | H3: 2010 | I3: 2011 | J3: 2012 | K3: 2013 | L3: 2014 | M3: 2015 | N3: 2016 | O3: 2017 | P3: 2018 | Q3: 2019 | R3: 2020 | S3: 2021 | T3: 2022 | U3: 2023 | V3: 2024 | W3: 2025 | X3: 2026 | Y3: 2027
B5: Market size estimate (patients) | D5: Total prostate cancer 2012 | G5: Defined market mCRPC
D6: Incidence | E6: Deaths | F6: Growth | I6: Assume | AA6: Epidemiology
B7: Prostate cancer to mCRPC | C7: US | D7: 233159 | E7: 30383 | F7: 0 | G7: % deaths | H7: Global | I7: 1 | J7: =$I$7 -> 1 | K7: =$I$7 -> 1 | L7: =$I$7 -> 1 | M7: =$I$7 -> 1 | N7: =$I$7 -> 1 | O7: =$I$7 -> 1 | P7: =$I$7 -> 1 | Q7: =$I$7 -> 1 | ... Y7: =$I$7 -> 1 | AA7: http://globocan.iarc.fr/old/FactSheets/cancers/prostate-new.asp
C8: EU | D8: 345195 | E8: 71789 | F8: 0 | G8: % incidence | H8: Global | I8: 0.015 | J8: 0 | K8: =J8+$I$8 -> 0.015 | L8: =K8+$I$8 -> 0.03 | M8: =L8+$I$8 -> 0.045 | N8: =M8+$I$8 -> 0.06 | O8: =N8+$I$8 -> 0.075 | P8: =O8+$I$8 -> 0.09 | Q8: =P8+$I$8 -> 0.105 | R8: =Q8+$I$8 -> 0.12 | ... Y8: =X8+$I$8 -> 0.225
C9: Total US and EU | D9: =D7+D8 -> 578354 | E9: =E7+E8 -> 102172
B11: Defined market mCRPC | C11: US | I11: US | J11: =$E$7*J7+$D$7*J8 -> 30383 | K11: =$E$7*K7+$D$7*K8 -> 33880.385 | L11: =$E$7*L7+$D$7*L8 -> 37377.77 | M11: =$E$7*M7+$D$7*M8 -> 40875.155 | N11: =$E$7*N7+$D$7*N8 -> 44372.54 | O11: =$E$7*O7+$D$7*O8 -> 47869.925 | P11: =$E$7*P7+$D$7*P8 -> 51367.31 | Q11: =$E$7*Q7+$D$7*Q8 -> 54864.695 | ... Y11: =$E$7*Y7+$D$7*Y8 -> 82843.775
C12: Non-US (EU + Australia, Canada) | E12: AU + CA = | F12: =AD45 -> 0.13971779 | I12: Non-US | J12: =($E$8*J7+$D$8*J8)*(1+$F$12) -> 81819.2 | K12: =($E$8*K7+$D$8*K8)*(1+$F$12) -> 87720.574 | L12: =($E$8*L7+$D$8*L8)*(1+$F$12) -> 93621.947 | M12: =($E$8*M7+$D$8*M8)*(1+$F$12) -> 99523.32 | N12: =($E$8*N7+$D$8*N8)*(1+$F$12) -> 105424.69 | O12: =($E$8*O7+$D$8*O8)*(1+$F$12) -> 111326.07 | P12: =($E$8*P7+$D$8*P8)*(1+$F$12) -> 117227.44 | Q12: =($E$8*Q7+$D$8*Q8)*(1+$F$12) -> 123128.81 | ... Y12: =($E$8*Y7+$D$8*Y8)*(1+$F$12) -> 170339.8
C13: Total US and Non-US | I13: Total | J13: =J11+J12 -> 112202.2 | K13: =K11+K12 -> 121600.96 | L13: =L11+L12 -> 130999.72 | M13: =M11+M12 -> 140398.48 | N13: =N11+N12 -> 149797.23 | O13: =O11+O12 -> 159195.99 | P13: =P11+P12 -> 168594.75 | Q13: =Q11+Q12 -> 177993.51 | ... Y13: =Y11+Y12 -> 253183.57
I14: % growth | K14: =K13/J13-1 -> 0.083766256 | L14: =L13/K13-1 -> 0.07729181 | M14: =M13/L13-1 -> 0.071746401 | N14: =N13/M13-1 -> 0.06694345 | O14: =O13/N13-1 -> 0.062743203 | P14: =P13/O13-1 -> 0.059038913 | Q14: =Q13/P13-1 -> 0.055747633 | R14: =R13/Q13-1 -> 0.052803938 | ... Y14: =Y13/X13-1 -> 0.038553501
B16: Market share | I16: US | J16: 0.27260196 | K16: 0.46058016 | L16: 0.57685741 | M16: 0.65913145 | N16: 0.68953284 | O16: 0.7 | P16: 0.71 | Q16: 0.72 | R16: 0.73 | S16: 0.74 | T16: 0.74 | U16: 0.74 | V16: 0.74 | W16: 0.74 | X16: 0.74 | Y16: 0.74
B17: Androgen synthesis inhibitors | I17: Non-US | J17: 0.1521271 | K17: 0.28365836 | L17: 0.42960892 | M17: 0.46278679 | N17: 0.52470259 | O17: 0.57 | P17: 0.61 | Q17: 0.64 | R17: 0.66 | S17: 0.67 | T17: 0.67 | U17: 0.67 | V17: 0.67 | W17: 0.67 | X17: 0.67 | Y17: 0.67
I18: Total | J18: =J22/J13 -> 0.18475024 | K18: =K22/K13 -> 0.33295221 | L18: =L22/L13 -> 0.4716229 | M18: =M22/M13 -> 0.51994993 | N18: =N22/N13 -> 0.57352817 | O18: =O22/O13 -> 0.60909075 | P18: =P22/P13 -> 0.64046792 | Q18: =Q22/Q13 -> 0.66465919 | ... Y18: =Y22/Y13 -> 0.69290458
B20: Patients treated with androgen synthesis inhibitors | I20: US | J20: =J16*J11 -> 8282.4652 | K20: =K16*K11 -> 15604.633 | L20: =L16*L11 -> 21561.643 | M20: =M16*M11 -> 26942.1 | N20: =N16*N11 -> 30596.323 | O20: =O16*O11 -> 33508.948 | P20: =P16*P11 -> 36470.79 | Q20: =Q16*Q11 -> 39502.58 | ... Y20: =Y16*Y11 -> 61304.394
B21: Assumes 12 mth treatment | I21: Non-US | J21: =J17*J12 -> 12446.918 | K21: =K17*K12 -> 24882.674 | L21: =L17*L12 -> 40220.823 | M21: =M17*M12 -> 46058.078 | N21: =N17*N12 -> 55316.61 | O21: =O17*O12 -> 63455.858 | P21: =P17*P12 -> 71508.738 | Q21: =Q17*Q12 -> 78802.44 | ... Y21: =Y17*Y12 -> 114127.67
I22: Total | J22: =J20+J21 -> 20729.383 | K22: =K20+K21 -> 40487.307 | L22: =L20+L21 -> 61782.466 | M22: =M20+M21 -> 73000.178 | N22: =N20+N21 -> 85912.933 | O22: =O20+O21 -> 96964.805 | P22: =P20+P21 -> 107979.53 | Q22: =Q20+Q21 -> 118305.02 | ... Y22: =Y20+Y21 -> 175432.06
I23: % growth | K23: =K22/J22-1 -> 0.95313614 | L23: =L22/K22-1 -> 0.52597123 | M23: =M22/L22-1 -> 0.18156788 | N23: =N22/M22-1 -> 0.17688663 | O23: =O22/N22-1 -> 0.12864038 | P23: =P22/O22-1 -> 0.11359506 | Q23: =Q22/P22-1 -> 0.095624537 | R23: =R22/Q22-1 -> 0.079956206 | ... Y23: =Y22/X22-1 -> 0.038735166
B24: Prolutamide | D24: Competing products | E24: TTP advantage | F24: Target price | G24: Share of Voice
B25: Market share | C25: US | D25: =Control!I5 -> 2 | E25: =Control!I6 -> 1 | F25: =Control!I7 -> 0 | G25: =IF(U49=1, 1)+IF(Control!I16>0,1,0) -> 2 | I25: US | J25: =$N$25*J54 -> 0.067979287 | K25: =$N$25*K54 -> 0.19806557 | L25: =$N$25*L54 -> 0.24832843 | M25: =$N$25*M54 -> 0.33641287 | N25: =G27-0.0018 -> 0.38153333 | O25: =N25+O56 -> 0.42153333 | P25: =O25+P56 -> 0.46153333 | Q25: =P25+Q56 -> 0.48153333 | R25: =Q25+R56 -> 0.50153333 | S25: =R25+S56 -> 0.50153333 | T25: =S25+T56 -> 0.50153333 | U25: =T25+U56 -> 0.49653333 | V25: =U25+V56 -> 0.48653333 | ... Y25: =X25+Y56 -> 0.45653333
C26: Non-US | E26: =E25 -> 1 | F26: =Control!I8 -> 0 | G26: =U50 -> 1 | I26: Non-US | J26: =$N$25*J55 -> 0 | K26: =$N$25*K55 -> 0.047297521 | L26: =$N$25*L55 -> 0.19864959 | M26: =$N$25*M55 -> 0.34054215 | N26: =G28 -> 0.40333333 | O26: =N26+O57 -> 0.44333333 | P26: =O26+P57 -> 0.46333333 | Q26: =P26+Q57 -> 0.48333333 | R26: =Q26+R57 -> 0.50333333 | S26: =R26+S57 -> 0.50333333 | T26: =S26+T57 -> 0.50333333 | U26: =T26+U57 -> 0.49833333 | V26: =U26+V57 -> 0.48833333 | ... Y26: =X26+Y57 -> 0.068333333
B27: Adjusted market share | C27: US | D27: =IF(D25=2,E49,H49) -> 0.33333333 | E27: =IF(E25=1,D27+K49,D27) -> 0.38333333 | F27: =IF(F25=0,Q49,IF(F25=-30%,S49,IF(F25=30%,R49))) -> 0.38333333 | G27: =IF(G25<1,F27*(1+V49),F27) -> 0.38333333 | I27: Total | J27: =J31/J22 -> 0.027161256 | K27: =K31/K22 -> 0.1054066 | L27: =L31/L22 -> 0.21598715 | M27: =M31/M22 -> 0.33901816 | N27: =N31/N22 -> 0.39556966 | O27: =O31/O22 -> 0.43579972 | P27: =P31/P22 -> 0.46272537 | Q27: =Q31/Q22 -> 0.48273231 | ... Y27: =Y31/Y22 -> 0.20398907 | AA27: Pricing | AC27: Price/cap $ | AD27: Popn m | AE27: Pr x pop
C28: Non-US | D28: =D27 -> 0.33333333 | E28: =IF(E26=1,D28+K50,D28) -> 0.40333333 | F28: =IF(F26=0,Q50,IF(F26=-30%,S50,IF(F26=30%,R50))) -> 0.40333333 | G28: =IF(G26=1,F28,F28*(1+V50)) -> 0.40333333 | AA28: 1 | AB28: Australia | AC28: 23.46 | AD28: 24.2 | AE28: =AC28*AD28 -> 567.732
B29: Patients | I29: US | J29: =J25*J20 -> 563.03608 | K29: =K25*K20 -> 3090.7405 | L29: =L25*L20 -> 5354.3692 | M29: =M25*M20 -> 9063.6693 | N29: =N25*N20 -> 11673.517 | O29: =O25*O20 -> 14125.138 | P29: =P25*P20 -> 16832.485 | Q29: =Q25*Q20 -> 19021.809 | ... Y29: =Y25*Y20 -> 27987.499 | AA29: 1 | AB29: Belgium | AC29: 31.48 | AD29: 11.2 | AE29: =AC29*AD29 -> 352.576
I30: Non-US | K30: =K26*K21 -> 1176.8888 | L30: =L26*L21 -> 7989.8499 | M30: =M26*M21 -> 15684.717 | N30: =N26*N21 -> 22311.033 | O30: =O26*O21 -> 28132.097 | P30: =P26*P21 -> 33132.382 | Q30: =Q26*Q21 -> 38087.846 | R30: =R26*R21 -> 42863.828 | ... Y30: =Y26*Y21 -> 7798.7238 | AA30: 1 | AB30: Canada | AC30: 30.12 | AD30: 36.2 | AE30: =AC30*AD30 -> 1090.344
I31: Total | J31: =J29+J30 -> 563.03608 | K31: =K29+K30 -> 4267.6293 | L31: =L29+L30 -> 13344.219 | M31: =M29+M30 -> 24748.386 | N31: =N29+N30 -> 33984.55 | O31: =O29+O30 -> 42257.235 | P31: =P29+P30 -> 49964.867 | Q31: =Q29+Q30 -> 57109.655 | ... Y31: =Y29+Y30 -> 35786.223 | AA31: 1 | AB31: France | AC31: 26.73 | AD31: 65.3 | AE31: =AC31*AD31 -> 1745.469
F32: Packaging | H32: Pack size | I32: % growth | K32: =K31/J31-1 -> 6.5796728 | L32: =L31/K31-1 -> 2.1268459 | M32: =M31/L31-1 -> 0.85461479 | N32: =N31/M31-1 -> 0.37320268 | O32: =O31/N31-1 -> 0.24342489 | P32: =P31/O31-1 -> 0.18239792 | Q32: =Q31/P31-1 -> 0.14299624 | R32: =R31/Q31-1 -> 0.12470148 | ... Y32: =Y31/X31-1 -> -0.54695915 | AA32: 1 | AB32: Germany | AC32: 36.93 | AD32: 82.5 | AE32: =AC32*AD32 -> 3046.725
C33: Dose / day (mg) | E33: 160 | F33: Bottle / blister | H33: 100 | AA33: 1 | AB33: Italy | AC33: 26.01 | AD33: 61.2 | AE33: =AC33*AD33 -> 1591.812
B34: Packs sold 000 | C34: Capsule size (mg) | E34: 40 | I34: US | J34: =$H$36*J29/1000 -> 8.2203267 | K34: =$H$36*K29/1000 -> 45.124811 | L34: =$H$36*L29/1000 -> 78.17379 | M34: =$H$36*M29/1000 -> 132.32957 | N34: =$H$36*N29/1000 -> 170.43335 | O34: =$H$36*O29/1000 -> 206.22702 | P34: =$H$36*P29/1000 -> 245.75429 | Q34: =$H$36*Q29/1000 -> 277.71841 | ... Y34: =$H$36*Y29/1000 -> 408.61749 | AA34: 1 | AB34: Holland | AC34: 31.48 | AD34: 16.9 | AE34: =AC34*AD34 -> 532.012
C35: Treatment days | E35: 365 | I35: Non-US | J35: =$H$36*J30/1000 -> 0 | K35: =$H$36*K30/1000 -> 17.182577 | L35: =$H$36*L30/1000 -> 116.65181 | M35: =$H$36*M30/1000 -> 228.99686 | N35: =$H$36*N30/1000 -> 325.74108 | O35: =$H$36*O30/1000 -> 410.72862 | P35: =$H$36*P30/1000 -> 483.73278 | Q35: =$H$36*Q30/1000 -> 556.08255 | ... Y35: =$H$36*Y30/1000 -> 113.86137 | AA35: 1 | AB35: Norway | AC35: 32.43 | AD35: 5.2 | AE35: =AC35*AD35 -> 168.636
C36: Caps/patient per year | E36: =E33/E34*E35 -> 1460 | F36: Packs/patient per year | H36: =E36/H33 -> 14.6 | I36: Total | J36: =J34+J35 -> 8.2203267 | K36: =K34+K35 -> 62.307387 | L36: =L34+L35 -> 194.8256 | M36: =M34+M35 -> 361.32644 | N36: =N34+N35 -> 496.17443 | O36: =O34+O35 -> 616.95564 | P36: =P34+P35 -> 729.48706 | Q36: =Q34+Q35 -> 833.80097 | ... Y36: =Y34+Y35 -> 522.47885 | AA36: 1 | AB36: Spain | AC36: 32.38 | AD36: 47.3 | AE36: =AC36*AD36 -> 1531.574
AA37: 1 | AB37: Sweden | AC37: 26.96 | AD37: 9.8 | AE37: =AC37*AD37 -> 264.208
B38: Sales forecast $m | D38: Target 2012 Wholesale price $ | G38: Prem/disc | H38: Fcast price | I38: US | J38: =J34*$H$40/1000 -> 71.165835 | K38: =K34*$H$40/1000 -> 390.65902 | L38: =L34*$H$40/1000 -> 676.77395 | M38: =M34*$H$40/1000 -> 1145.6168 | N38: =N34*$H$40/1000 -> 1475.4927 | O38: =O34*$H$40/1000 -> 1785.3692 | P38: =P34*$H$40/1000 -> 2127.5686 | Q38: =Q34*$H$40/1000 -> 2404.2916 | ... Y38: =Y34*$H$40/1000 -> 3537.5242 | AA38: 1 | AB38: Switzer | AC38: 35.46 | AD38: 8.3 | AE38: =AC38*AD38 -> 294.318
D39: Per cap | E39: Per pack 100 | F39: Treatment | G39: Pack 100 | H39: Pack 100 | I39: Non-US | J39: =J35*$H$41/1000 -> 0 | K39: =K35*$H$41/1000 -> 53.555488 | L39: =L35*$H$41/1000 -> 363.58601 | M39: =M35*$H$41/1000 -> 713.74853 | N39: =N35*$H$41/1000 -> 1015.2856 | O39: =O35*$H$41/1000 -> 1280.1789 | P39: =P35*$H$41/1000 -> 1507.7218 | Q39: =Q35*$H$41/1000 -> 1733.2251 | ... Y39: =Y35*$H$41/1000 -> 354.88863 | AA39: 1 | AB39: UK | AC39: 35.65 | AD39: 64.2 | AE39: =AC39*AD39 -> 2288.73
C40: US | D40: =AE49 -> 86.573 | E40: =AE49*$H$33 -> 8657.3 | F40: =D40*E36 -> 126396.58 | G40: =F25 -> 0 | H40: =E40*(1+G40) -> 8657.3 | I40: Total | J40: =J38+J39 -> 71.165835 | K40: =K38+K39 -> 444.21451 | L40: =L38+L39 -> 1040.36 | M40: =M38+M39 -> 1859.3653 | N40: =N38+N39 -> 2490.7782 | O40: =O38+O39 -> 3065.548 | P40: =P38+P39 -> 3635.2904 | Q40: =Q38+Q39 -> 4137.5167 | ... Y40: =Y38+Y39 -> 3892.4128 | AA40: =SUM(AA28:AA39) -> 12 | AB40: Total | AC40: =SUM(AC28:AC39) -> 369.09 | AD40: =SUM(AD28:AD39) -> 432.3 | AE40: =SUM(AE28:AE39) -> 13474.136
C41: Non-US | D41: =AE41 -> 31.168485 | E41: =AE50*$H$33 -> 3116.8485 | F41: =E36*D41 -> 45505.988 | G41: =F26 -> 0 | H41: =E41*(1+G41) -> 3116.8485 | I41: % growth | K41: =K40/J40-1 -> 5.2419631 | L41: =L40/K40-1 -> 1.3420216 | M41: =M40/L40-1 -> 0.78723269 | N41: =N40/M40-1 -> 0.33958518 | O41: =O40/N40-1 -> 0.23075912 | P41: =P40/O40-1 -> 0.18585333 | Q41: =Q40/P40-1 -> 0.13815302 | R41: =R40/Q40-1 -> 0.12418591 | ... Y41: =Y40/X40-1 -> -0.3300975 | AB41: Av pr | AC41: =AC40/AA40 -> 30.7575 | AD41: Wt av pr | AE41: =AE40/AD40 -> 31.168485
AA42: 1 | AB42: Japan | AC42: 26.37 | AD42: 126.6 | AE42: =AC42*AD42 -> 3338.442
C43: Average net selling price per patient treatment $000 | J43: =J40*1000/J31 -> 126.39658 | K43: =K40*1000/K31 -> 104.08929 | L43: =L40*1000/L31 -> 77.963346 | M43: =M40*1000/M31 -> 75.130771 | N43: =N40*1000/N31 -> 73.291488 | O43: =O40*1000/O31 -> 72.544927 | P43: =P40*1000/P31 -> 72.75693 | Q43: =Q40*1000/Q31 -> 72.448637 | ... Y43: =Y40*1000/Y31 -> 108.76847 | AA43: =AA42+AA40 -> 13 | AB43: Av pr | AC43: =(AC40+AC42)/AA43 -> 30.42 | AD43: Wt av pr | AE43: =+(AE40+AE42)/(AD40+AD42) -> 30.081549
C44: Average net selling price per pack 100 caps $000 | J44: =J43/$H$36 -> 8.6573 | K44: =K43/$H$36 -> 7.1294036 | L44: =L43/$H$36 -> 5.3399552 | M44: =M43/$H$36 -> 5.1459432 | N44: =N43/$H$36 -> 5.0199649 | O44: =O43/$H$36 -> 4.9688306 | P44: =P43/$H$36 -> 4.9833514 | Q44: =Q43/$H$36 -> 4.9622354 | ... Y44: =Y43/$H$36 -> 7.4498954 | AB44: ANZ,CA | AD44: =AD28+AD30 -> 60.4
...

Sheet COG
A1: COST OF GOODS | E1: Assumptions in red | G1: Assumptions in yellow box from control panel
C2: Flucitra 120mg capsule pilot scale cost | E2: Pilot scale cost of goods per capsule for clinical trial supplies | K2: =G23/30*L2 -> 1067.3704 | L2: 100 | M2: pilot scalefactor
A3: Licensee Buys Finished Packs from Licensor (at 2009 Costs) | N3: Licensee Manufactures and Packs Inhouse (at 2009 Costs)
B4: Assumptions | E4: Batch size kg | G4: 25 | I4: Batch size kg | K4: 50 | N4: Batch size kg | S4: =G4 -> 25 | U4: Batch size kg | W4: =K4 -> 50
E5: API cost per kg $ | G5: 15000 | I5: =E5 -> API cost per kg $ | K5: =G5 -> 15000 | Q5: =E5 -> API cost per kg $ | S5: =G5 -> 15000 | U5: =Q5 -> API cost per kg $ | W5: =G5 -> 15000
E6: API Cost / batch $ | G6: =G4*G5 -> 375000 | I6: =E6 -> API Cost / batch $ | K6: =K4*K5 -> 750000 | Q6: =E6 -> API Cost / batch $ | S6: =S4*S5 -> 375000 | U6: =Q6 -> API Cost / batch $ | W6: =W4*W5 -> 750000
E7: Yield | G7: 0.9 | I7: Yield | K7: =G7 -> 0.9 | Q7: Yield | S7: =G7 -> 0.9 | U7: =Q7 -> Yield | W7: =K7 -> 0.9
E8: Caps API mg | G8: =G4*G7*1000000 -> 22500000 | I8: =E8 -> Caps API mg | K8: =K4*K7*1000000 -> 45000000 | Q8: =E8 -> Caps API mg | S8: =S4*S7*1000000 -> 22500000 | U8: =Q8 -> Caps API mg | W8: =W4*W7*1000000 -> 45000000
E9: Mg per cap | G9: 40 | I9: =E9 -> Mg per cap | K9: =G9 -> 40 | Q9: =E9 -> Mg per cap | S9: =G9 -> 40 | U9: =Q9 -> Mg per cap | W9: =S9 -> 40
E10: Caps per batch | G10: =G8/G9 -> 562500 | I10: =E10 -> Caps per batch | K10: =K8/K9 -> 1125000 | Q10: =E10 -> Caps per batch | S10: =S8/S9 -> 562500 | U10: =Q10 -> Caps per batch | W10: =W8/W9 -> 1125000
C11: =100*2.18 -> 218 | E11: Pack size caps | G11: 100 | I11: =E11 -> Pack size caps | K11: =G11 -> 100 | Q11: =E11 -> Pack size caps | S11: =G11 -> 100 | U11: =Q11 -> Pack size caps | W11: =S11 -> 100
E12: Packs per batch | G12: =G10/G11 -> 5625 | I12: =E12 -> Packs per batch | K12: =K10/K11 -> 11250 | Q12: =E12 -> Packs per batch | S12: =S10/S11 -> 5625 | U12: =Q12 -> Packs per batch | W12: =W10/W11 -> 11250
B14: Variable costs | G14: Cost / pack $ | K14: Cost / pack $ | S14: =G14 -> Cost / pack $ | W14: =S14 -> Cost / pack $
C15: API | G15: =G6/G12 -> 66.666667 | K15: =K6/K12 -> 66.666667 | N15: API | S15: =S6/S12 -> 66.666667 | W15: =W6/W12 -> 66.666667
C16: Packing materials and excipients | G16: 17 | K16: =G16 -> 17 | N16: Packing materials and excipients | S16: =G16 -> 17 | W16: =S16 -> 17
C17: Direct labour | G17: 17 | K17: =G17 -> 17 | N17: Direct labour | S17: =G17 -> 17 | W17: =S17 -> 17
C18: Total variable costs | G18: =SUM(G15:G17) -> 100.66667 | K18: =SUM(K15:K17) -> 100.66667 | N18: Total variable costs | S18: =SUM(S15:S17) -> 100.66667 | W18: =SUM(W15:W17) -> 100.66667
B19: Fixed costs | N19: Fixed costs
C20: Fixed costs | F20: 1000 | G20: =F20/G12*1000 -> 177.77778 | J20: =F20 -> 1000 | K20: =J20/K12*1000 -> 88.888889 | O20: Fixed costs | R20: =F20 -> 1000 | S20: =R20/S12*1000 -> 177.77778 | V20: =R20 -> 1000 | W20: =V20/W12*1000 -> 88.888889
B21: Total variable and fixed costs | G21: =G20+G18 -> 278.44444 | K21: =K20+K18 -> 189.55556 | N21: Total variable and fixed costs | S21: =S18+S20 -> 278.44444 | W21: =W18+W20 -> 189.55556
C22: Shipping and insurance and CMO profit | E22: CMO profit | F22: 0.15 | G22: =F22*G21 -> 41.766667 | J22: =F22 -> 0.15 | K22: =J22*K21 -> 28.433333 | O22: Shipping and insurance | R22: 0.02 | S22: =R22*S21 -> 5.5688889 | V22: =R22 -> 0.02 | W22: =V22*W21 -> 3.7911111
B23: Total costs | G23: =G21+G22 -> 320.21111 | K23: =K21+K22 -> 217.98889 | N23: Total costs excluding depreciation | Q23: Capex $m | R23: Capacity m | S23: =S21+S22 -> 284.01333 | U23: Capex $m | V23: Capacity m | W23: =W21+W22 -> 193.34667
C24: Licensor mark-up | F24: =Control!I12 -> 0.25 | G24: =F24*G23 -> 80.052778 | J24: =Control!I12 -> 0.25 | K24: =J24*K23 -> 54.497222 | N24: Depreciation | Q24: 15 | R24: =Sales!I70 -> 23.586961 | S24: =Q24/R24 -> 0.63594458 | U24: 30 | V24: =Sales!I71 -> 979.97892 | W24: =U24/V24 -> 0.030612903
B25: Total supply price to licensee | G25: =G23+G24 -> 400.26389 | K25: =K23+K24 -> 272.48611 | N25: Total cost of goods | S25: =S23+S24 -> 284.64928 | W25: =W23+W24 -> 193.37728
C26: Average net selling price per pack 2016 | G26: =Sales!$N$44*1000 -> 5019.9649 | K26: =G26 -> 5019.9649 | O26: Net selling price | S26: =G26 -> 5019.9649 | W26: =K26 -> 5019.9649
C27: COG % net selling price | G27: =G25/G26 -> 0.079734399 | K27: =K25/K26 -> 0.054280481 | O27: COG % net selling price | S27: =S25/S26 -> 0.056703439 | W27: =W25/W26 -> 0.038521639
C28: Assumes annual cost increases affecting direct and indirect costs are offset by savings from improvement in productivity
A30: Cost/benefit Licensee inhouse manufacture | E30: =Control!Y2 -> 2008 | F30: =E30+1 -> 2009 | G30: =F30+1 -> 2010 | H30: =G30+1 -> 2011 | I30: =H30+1 -> 2012 | J30: =I30+1 -> 2013 | K30: =J30+1 -> 2014 | L30: =K30+1 -> 2015 | M30: =L30+1 -> 2016 | ... R30: =Q30+1 -> 2021
C31: Volume of packs 000 | I31: =Sales!J63 -> 8.2203267 | J31: =Sales!K63 -> 62.307387 | K31: =Sales!L63 -> 194.8256 | L31: =Sales!M63 -> 361.32644 | M31: =Sales!N63 -> 496.17443 | N31: =Sales!O63 -> 616.95564 | O31: =Sales!P63 -> 729.48706 | P31: =Sales!Q63 -> 833.80097 | ... R31: =Sales!S63 -> 999.53953
B32: If Licensor supply
C33: Supply price per pack | D33: $ | I33: =IF(Sales!J70>0,COG!$G$25,COG!$K$25) -> 400.26389 | J33: =IF(Sales!K70>0,COG!$G$25,COG!$K$25) -> 400.26389 | K33: =IF(Sales!L70>0,COG!$G$25,COG!$K$25) -> 400.26389 | L33: =IF(Sales!M70>0,COG!$G$25,COG!$K$25) -> 272.48611 | M33: =IF(Sales!N70>0,COG!$G$25,COG!$K$25) -> 272.48611 | N33: =IF(Sales!O70>0,COG!$G$25,COG!$K$25) -> 272.48611 | O33: =IF(Sales!P70>0,COG!$G$25,COG!$K$25) -> 272.48611 | P33: =IF(Sales!Q70>0,COG!$G$25,COG!$K$25) -> 272.48611 | ... R33: =IF(Sales!S70>0,COG!$G$25,COG!$K$25) -> 272.48611
C34: Cost of goods | D34: $m | I34: =I31*I33/1000 -> 3.2903 | J34: =J31*J33/1000 -> 24.939397 | K34: =K31*K33/1000 -> 77.981651 | L34: =L31*L33/1000 -> 98.456435 | M34: =M31*M33/1000 -> 135.20064 | N34: =N31*N33/1000 -> 168.11184 | O34: =O31*O33/1000 -> 198.77509 | P34: =P31*P33/1000 -> 227.19918 | ... R34: =R31*R33/1000 -> 272.36064
B35: If Licensee inhouse manufacture
C36: If investment of $15m
C37: Cost per pack | D37: $ | I37: =$S$25 -> 284.64928 | J37: =$S$25 -> 284.64928 | K37: =$S$25 -> 284.64928 | L37: =$S$25 -> 284.64928 | M37: =$S$25 -> 284.64928 | N37: =$S$25 -> 284.64928 | O37: =$S$25 -> 284.64928 | P37: =$S$25 -> 284.64928 | ... R37: =$S$25 -> 284.64928
C38: Cost of goods | D38: $m | H38: =H37*H31 -> 0 | I38: =I37*I31/1000 -> 2.3399101 | J38: =J37*J31/1000 -> 17.735753 | K38: =K37*K31/1000 -> 55.456966 | L38: =L37*L31/1000 -> 102.85131 | M38: =M37*M31/1000 -> 141.23569 | N38: =N37*N31/1000 -> 175.61598 | O38: =O37*O31/1000 -> 207.64797 | P38: =P37*P31/1000 -> 237.34084 | ... R38: =R37*R31/1000 -> 284.5182
C39: Saving or (loss) from inhouse manufacture | D39: $m | H39: =H34-H38 -> 0 | I39: =I34-I38 -> 0.95038988 | J39: =J34-J38 -> 7.2036444 | K39: =K34-K38 -> 22.524686 | L39: =L34-L38 -> -4.3948737 | M39: =M34-M38 -> -6.0350523 | N39: =N34-N38 -> -7.5041343 | O39: =O34-O38 -> -8.8728728 | ... R39: =R34-R38 -> -12.157566
C40: Capital expenditure if inhouse manufacture | D40: $m | G40: =-Q24 -> -15
C41: Cash flow | E41: =E39+E40 -> 0 | F41: =F39+F40 -> 0 | G41: =G39+G40 -> -15 | H41: =H39+H40 -> 0 | I41: =I39+I40 -> 0.95038988 | J41: =J39+J40 -> 7.2036444 | K41: =K39+K40 -> 22.524686 | L41: =L39+L40 -> -4.3948737 | ... R41: =R39+R40 -> -12.157566
C42: NPV | D42: =Control!G45 -> 0.12 | E42: NPV | F42: =NPV(D42,H41:R41)+G41 -> -18.154237 | G42: IRR | H42: =IRR(G41:R41) -> #NUM!
...

Sheet R&D
A1: DEVELOPMENT AND REGULATORY
C2: Assumptions in yellow box from control panel | F2: Are additional patients needed for the biclautamide studies? | G2: =Control!V10 -> 0 | H2: 1 = YES | L2: 1 | M2: =L2+1 -> 2 | N2: =M2+1 -> 3 | O2: =N2+1 -> 4 | P2: =O2+1 -> 5 | Q2: =P2+1 -> 6 | R2: =Q2+1 -> 7 | S2: =R2+1 -> 8 | T2: =S2+1 -> 9 | U2: =T2+1 -> 10 | V2: Total
E3: 2005 | F3: 2006 | G3: 2007 | H3: 2008 | I3: 2009 | J3: 2010 | K3: 2011 | L3: 2012 | M3: 2013 | N3: 2014 | O3: 2015 | P3: 2016 | Q3: 2017 | R3: 2018 | S3: 2019 | T3: 2020 | U3: 2021 | V3: 2009-21
C4: Synthesise, test and identify lead compound from 170 compounds | E4: 0.087 | F4: 1.007 | V4: =SUM(I4:U4) -> 0
C5: Manufacture lead compound for IND enabling preclinical and early clinical studies and scale up | E5: 0.087 | F5: 1.007 | G5: 1 | H5: 2.2 | I5: 4.9 | J5: 5.4 | K5: 6.7 | L5: 7 | M5: 7.5 | N5: 8 | O5: 8.5 | V5: =SUM(I5:U5) -> 48
C6: Complete IND enabling preclinical studies and file IND | E6: 0.087 | F6: 1.007 | G6: 0.5 | V6: =SUM(I6:U6) -> 0
C7: Total non-clinical | E7: =SUM(E4:E6) -> 0.261 | F7: =SUM(F4:F6) -> 3.021 | G7: =SUM(G4:G6) -> 1.5 | H7: =SUM(H4:H6) -> 2.2 | I7: =SUM(I4:I6) -> 4.9 | J7: =SUM(J4:J6) -> 5.4 | K7: =SUM(K4:K6) -> 6.7 | L7: =SUM(L4:L6) -> 7 | ... U7: =SUM(U4:U6) -> 0 | V7: =SUM(I7:U7) -> 48
C8: Prostate cancer clinical studies
C9: Combined Phase 1 / 2a clinical study | G9: =T51 -> 1.10211 | V9: =SUM(I9:U9) -> 0
C10: Extension | H10: =T52 -> 6.6948 | V10: =SUM(I10:U10) -> 0
C11: AFFIRM: Phase 3 DB extended to open label | I11: =$T$53*U53 -> 14.024655 | J11: =$T$53*V53 -> 27.411826 | K11: =$T$53*W53 -> 22.311951 | L11: =K11 -> 22.311951 | M11: =L11 -> 22.311951 | N11: =M11 -> 22.311951 | O11: =N11 -> 22.311951 | P11: =O11 -> 22.311951 | V11: =SUM(I11:U11) -> 175.30819
C12: PREVAIL: Phase 3 DB extended to open label | J12: =$T$54*V54 -> 23.72894 | K12: =$T$54*W54 -> 52.203668 | L12: =$T$54*X54 -> 18.983152 | M12: =L12 -> 18.983152 | N12: =M12 -> 18.983152 | O12: 10 | V12: =SUM(I12:U12) -> 142.88206
C13: TERRAIN: Phase 2 DB extended to open label | K13: =$T$55*W55 -> 5.08125 | L13: =$T$55*X55 -> 5.08125 | M13: =$T$55*Y55 -> 10.1625 | N13: =M13 -> 10.1625 | O13: =N13 -> 10.1625 | P13: =O13 -> 10.1625 | V13: =SUM(I13:U13) -> 50.8125
C14: STRIVE: Phase 2 DB, | L14: =$T$56*X56 -> 10.997712 | M14: =$T$56*Y56 -> 10.997712 | V14: =SUM(I14:U14) -> 21.995424
C15: PLATO: Phase 4 | L15: =$T$57*X57 -> 26.91592 | M15: =$T$57*Y57 -> 18.841144 | N15: =$T$57*Z57 -> 8.074776 | O15: =N15 -> 8.074776 | P15: =O15 -> 8.074776 | V15: =SUM(I15:U15) -> 69.981392
C16: PROSPER: Phase 3 DB | L16: =$T$58*X58 -> 13.04784 | M16: =$T$58*Y58 -> 21.7464 | N16: =$T$58*Z58 -> 21.7464 | O16: =$T$58*AA58 -> 30.44496 | V16: =SUM(I16:U16) -> 86.9856
C17: EMBARK: Phase 3 | N17: =$T$59*Z59 -> 41.48544 | O17: =$T$59*AA59 -> 36.29976 | P17: =$T$59*AB59 -> 25.9284 | V17: =SUM(I17:U17) -> 103.7136
C18: M1 HSPC | P18: =$T$60*AB60 -> 15.334 | Q18: =$T$60*AC60 -> 30.668 | R18: =$T$60*AD60 -> 15.334 | V18: =SUM(I18:U18) -> 61.336
C19: Other Prolutamide prostate cancer studies | L19: 2.7 | M19: 0.9 | N19: 2.2 | O19: 4.3 | Q19: 20 | R19: =Q19 -> 20 | S19: =R19 -> 20 | T19: =S19 -> 20 | U19: =T19 -> 20 | V19: =SUM(I19:U19) -> 110.1
C20: Total prostate cancer phase 3 | G20: =SUM(G9:G19)-G15 -> 1.10211 | H20: =SUM(H9:H19)-H15 -> 6.6948 | I20: =SUM(I9:I19)-I15 -> 14.024655 | J20: =SUM(J9:J19)-J15 -> 51.140766 | K20: =SUM(K9:K19)-K15 -> 79.596869 | L20: =SUM(L9:L19)-L15 -> 73.121905 | M20: =SUM(M9:M19)-M15 -> 85.101715 | N20: =SUM(N9:N19)-N15 -> 116.88944 | ... U20: =SUM(U9:U19)-U15 -> 20 | V20: =SUM(I20:U20) -> 753.13338
C21: Total prostate cancer Phase 4 | G21: =G15 -> 0 | H21: =H15 -> 0 | I21: =I15 -> 0 | J21: =J15 -> 0 | K21: =K15 -> 0 | L21: =L15 -> 26.91592 | M21: =M15 -> 18.841144 | N21: =N15 -> 8.074776 | ... U21: =U15 -> 0 | V21: =SUM(I21:U21) -> 69.981392
C22: Breast cancer | V22: =SUM(I22:U22) -> 0
C23: AR+ TNBC Phase 2 open label | L23: =$T$62*X62 -> 3.06328 | M23: =$T$62*Y62 -> 3.06328 | V23: =SUM(I23:U23) -> 6.12656
C24: AR+ or PgR+ and HER normal Phase 2 DB, combo exemestane | M24: 3.20606 | N24: 6.41212 | O24: 3.20606 | V24: =SUM(I24:U24) -> 12.82424
C25: AR+ HER2 Amplfied Phase 2, Xtandi added to trastuzumab | N25: =$T$64*Z64 -> 1.0576 | O25: =$T$64*AA64 -> 2.1152 | P25: =$T$64*AB64 -> 1.0576 | V25: =SUM(I25:U25) -> 4.2304
C26: Liver cancer | V26: =SUM(I26:U26) -> 0
C27: Phase 2 | P27: =$T$66*AB66 -> 1.85184 | Q27: =$T$66*AC66 -> 3.70368 | R27: =$T$66*AD66 -> 1.85184 | V27: =SUM(I27:U27) -> 7.40736
C28: Total non prostate cancer studies | E28: =SUM(E23:E27) -> 0 | F28: =SUM(F23:F27) -> 0 | G28: =SUM(G23:G27) -> 0 | H28: =SUM(H23:H27) -> 0 | I28: =SUM(I23:I27) -> 0 | J28: =SUM(J23:J27) -> 0 | K28: =SUM(K23:K27) -> 0 | L28: =SUM(L23:L27) -> 3.06328 | ... U28: =SUM(U23:U27) -> 0 | V28: =SUM(I28:U28) -> 30.58856
C29: Total clinical costs | E29: =E20+E21+E28 -> 0 | F29: =F20+F21+F28 -> 0 | G29: =G20+G21+G28 -> 1.10211 | H29: =H20+H21+H28 -> 6.6948 | I29: =I20+I21+I28 -> 14.024655 | J29: =J20+J21+J28 -> 51.140766 | K29: =K20+K21+K28 -> 79.596869 | L29: =L20+L21+L28 -> 103.10111 | ... U29: =U20+U21+U28 -> 20 | V29: =SUM(I29:U29) -> 853.70333
C30: Total R&D | E30: =E29+E7 -> 0.261 | F30: =F29+F7 -> 3.021 | G30: =G29+G7 -> 2.60211 | H30: =H29+H7 -> 8.8948 | I30: =I29+I7 -> 18.924655 | J30: =J29+J7 -> 56.540766 | K30: =K29+K7 -> 86.296869 | L30: =L29+L7 -> 110.10111 | ... U30: =U29+U7 -> 20 | V30: =SUM(I30:U30) -> 901.70333
E31: 0.261 | F31: 3.021 | G31: 2.60211 | H31: 8.8948 | I31: 18.924655 | J31: 56.540766 | K31: 86.296869 | L31: 110.10111 | M31: 117.7122 | N31: 140.43394 | O31: 135.41521 | P31: 84.721067 | Q31: 34.37168 | R31: 17.18584 | S31: 0 | T31: 0 | U31: 0
A32: R&D Costs Paid by Licensee/Lor | E32: % Lee pays? | V32: Total
C33: Manufacture lead compound for IND enabling preclinical and early clinical studies and scale up | E33: =Control!F22 -> 0.5 | I33: =$E$33*I7 -> 2.45 | J33: =$E$33*J7 -> 2.7 | K33: =$E$33*K7 -> 3.35 | L33: =$E$33*L7 -> 3.5 | M33: =$E$33*M7 -> 3.75 | N33: =$E$33*N7 -> 4 | O33: =$E$33*O7 -> 4.25 | P33: =$E$33*P7 -> 0 | ... U33: =$E$33*U7 -> 0 | V33: =SUM(I33:U33) -> 24
C34: Total prostate cancer phase 3 | E34: =Control!F23 -> 1 | I34: =$E$34*I20 -> 14.024655 | J34: =$E$34*J20 -> 51.140766 | K34: =$E$34*K20 -> 79.596869 | L34: =$E$34*L20 -> 73.121905 | M34: =$E$34*M20 -> 85.101715 | N34: =$E$34*N20 -> 116.88944 | O34: =$E$34*O20 -> 113.51917 | P34: =$E$34*P20 -> 73.736851 | ... U34: =$E$34*U20 -> 20 | V34: =SUM(I34:U34) -> 753.13338
C35: Total prostate cancer Phase 4 | E35: =Control!F24 -> 1 | I35: =$E$35*I21 -> 0 | J35: =$E$35*J21 -> 0 | K35: =$E$35*K21 -> 0 | L35: =$E$35*L21 -> 26.91592 | M35: =$E$35*M21 -> 18.841144 | N35: =$E$35*N21 -> 8.074776 | O35: =$E$35*O21 -> 8.074776 | P35: =$E$35*P21 -> 8.074776 | ... U35: =$E$35*U21 -> 0 | V35: =SUM(I35:U35) -> 69.981392
C36: Total non prostate cancer studies | E36: =Control!F25 -> 0.5 | I36: =$E$36*I28 -> 0 | J36: =$E$36*J28 -> 0 | K36: =$E$36*K28 -> 0 | L36: =$E$36*L28 -> 1.53164 | M36: =$E$36*M28 -> 3.13467 | N36: =$E$36*N28 -> 3.73486 | O36: =$E$36*O28 -> 2.66063 | P36: =$E$36*P28 -> 1.45472 | ... U36: =$E$36*U28 -> 0 | V36: =SUM(I36:U36) -> 15.29428
B37: Licensee costs (to Lee vs Lor sheet) | E37: =SUM(G37:U37) -> 862.40905 | F37: =SUM(F33:F36) -> 0 | G37: =SUM(G33:G36) -> 0 | H37: =SUM(H33:H36) -> 0 | I37: =SUM(I33:I36) -> 16.474655 | J37: =SUM(J33:J36) -> 53.840766 | K37: =SUM(K33:K36) -> 82.946869 | L37: =SUM(L33:L36) -> 105.06947 | M37: =SUM(M33:M36) -> 110.82753 | ... U37: =SUM(U33:U36) -> 20 | V37: =SUM(I37:U37) -> 862.40905
B38: Licensor costs (to Lee vs Lor sheet) | E38: =SUM(G38:U38) -> 39.29428 | I38: =I30-I37 -> 2.45 | J38: =J30-J37 -> 2.7 | K38: =K30-K37 -> 3.35 | L38: =L30-L37 -> 5.03164 | M38: =M30-M37 -> 6.88467 | N38: =N30-N37 -> 7.73486 | O38: =O30-O37 -> 6.91063 | P38: =P30-P37 -> 1.45472 | ... U38: =U30-U37 -> 0 | V38: =SUM(I38:U38) -> 39.29428
A40: R&D Costs used in Project P&L | I40: Phase 3 | J40: Phase 3 | K40: Regulatory | L40: Launch
B41: Project | I41: =I3 -> 2009 | J41: =J3 -> 2010 | K41: =K3 -> 2011 | L41: =L3 -> 2012 | M41: =M3 -> 2013 | N41: =N3 -> 2014 | O41: =O3 -> 2015 | P41: =P3 -> 2016 | ... U41: =U3 -> 2021 | V41: Total
...

Sheet S&M
A1: SALES AND MARKETING | D1: Assumptions in red | F1: =Control!Y2 -> 2008 | G1: Assumptions in yellow box from control panel
B3: Hospital and KOL Salesmen | D3: US | E3: Non US | F3: Total | H3: Payers | K3: US | L3: Non US | M3: Total
C4: Target audience urologist / oncologist | D4: 10000 | E4: 20000 | F4: =D4+E4 -> 30000 | H4: Total payer accounts | K4: 5000 | L4: 10000 | M4: =K4+L4 -> 15000
C5: Target calls per doctor per annum | D5: 12 | E5: 12 | H5: Accounts per executive | K5: 25 | L5: 25
C6: Target calls per annum | D6: =D4*D5 -> 120000 | E6: =E4*E5 -> 240000 | F6: =D6+E6 -> 360000 | H6: Number of major account managers | K6: =K4/K5 -> 200 | L6: =L4/L5 -> 400
C7: Working days per salesman | D7: 200 | E7: 200 | H7: Cost per manager $000 | J7: 0.25 | K7: =D11*(1+$J$7) -> 250 | L7: =E11*(1+$J$7) -> 187.5
C8: Calls per day per salesman | D8: 3 | E8: 3 | H8: Total costs $m | K8: =K6*K7/1000 -> 50 | L8: =L6*L7/1000 -> 75 | M8: =K8+L8 -> 125
C9: Annual calls per salesman | D9: =D7*D8 -> 600 | E9: =E7*E8 -> 600 | H9: Apportionment
C10: Number of salesmen | D10: =D6/D9 -> 200 | E10: =E6/E9 -> 400 | H10: % time dealing with prolutamide | K10: 0.5 | L10: 0.75 | M10: =M11/M8 -> 0.65
C11: Cost per salesman $000 | D11: 200 | E11: 150 | H11: Apportioned cost | K11: =K8*K10 -> 25 | L11: =L8*L10 -> 56.25 | M11: =K11+L11 -> 81.25
C12: Total employment costs $m | D12: =D10*D11/1000 -> 40 | E12: =E10*E11/1000 -> 60 | F12: =D12+E12 -> 100
C13: Cost per call $ | D13: =D12/D6*1000000 -> 333.33333 | E13: =E12/E6*1000000 -> 250 | F13: =F12/F6*1000000 -> 277.77778 | H13: Marketing Executives | K13: US | L13: Non US | M13: Total
B14: Salesforce Meetings | D14: US | E14: Non US | F14: Total | H14: Headcount | K14: 50 | L14: 100 | M14: =K14+L14 -> 150
C15: Target audience | D15: =D4 -> 10000 | E15: =E4 -> 20000 | F15: =F4 -> 30000 | H15: Cost per head $000 | K15: 300 | L15: 200
C16: Physicians per meeting | D16: 6 | E16: 6 | H16: Total employment costs $m | K16: =K14*K15/1000 -> 15 | L16: =L14*L15/1000 -> 20 | M16: =K16+L16 -> 35
C17: Meetings per annum | D17: =D15/D16 -> 1666.6667 | E17: =E15/E16 -> 3333.3333 | H17: Marketing
C18: Cost per meeting $000 | D18: 2 | E18: 3 | H18: Advertising | K18: 2 | L18: 4
C19: Total costs $m | D19: =D17*D18/1000 -> 3.3333333 | E19: =E17*E18/1000 -> 10 | F19: =D19+E19 -> 13.333333 | H19: PR | K19: 4 | L19: 8
B20: Total hospital and KOL salesforce costs $m | D20: =D19+D12 -> 43.333333 | E20: =E19+E12 -> 70 | F20: =D20+E20 -> 113.33333 | H20: Total costs $m | K20: =K18+K19 -> 6 | L20: =L18+L19 -> 12 | M20: =K20+L20 -> 18
B21: Total S&M | D21: =D20+K11+K25 -> 109.33333 | E21: =E20+L11+L25 -> 178.25 | F21: =D21+E21 -> 287.58333 | H21: Symposia
H22: Number per year | K22: 4 | L22: 4
B23: Apportionment | E23: Full time on target product | F23: 1 | H23: Cost $m | K23: 5 | L23: 5
E24: First line detail 2 products | F24: 0.65 | H24: Total costs $m | K24: =K22*K23 -> 20 | L24: =L22*L23 -> 20 | M24: =K24+L24 -> 40
E25: Second line detail 2 products | F25: 0.35 | H25: Total marketing costs | K25: =K24+K20+K16 -> 41 | L25: =L24+L20+L16 -> 52 | M25: =M24+M20+M16 -> 93
A28: Sales and marketing costs | E28: =F1+1 -> 2009 | F28: =E28+1 -> 2010 | G28: =F28+1 -> 2011 | H28: =G28+1 -> 2012 | I28: =H28+1 -> 2013 | J28: =I28+1 -> 2014 | K28: =J28+1 -> 2015 | L28: =K28+1 -> 2016 | M28: =L28+1 -> 2017 | ... Q28: =P28+1 -> 2021
B29: US | H29: =Control!I14 -> 1 | I29: =H29 -> 1 | J29: =I29 -> 1 | K29: =J29 -> 1 | L29: =K29 -> 1 | M29: =Control!J14 -> 1 | N29: =M29 -> 1 | O29: =N29 -> 1 | P29: =O29 -> 1 | Q29: =P29 -> 1
C30: Apportioned salesforce cost $m | H30: =$D$20*H29 -> 43.333333 | I30: =$D$20*I29 -> 43.333333 | J30: =$D$20*J29 -> 43.333333 | K30: =$D$20*K29 -> 43.333333 | L30: =$D$20*L29 -> 43.333333 | M30: =$D$20*M29 -> 43.333333 | N30: =$D$20*N29 -> 43.333333 | O30: =$D$20*O29 -> 43.333333 | ... Q30: =$D$20*Q29 -> 43.333333
C31: Payer management | H31: =K11 -> 25 | I31: =H31 -> 25 | J31: =I31 -> 25 | K31: =J31 -> 25 | L31: =K31 -> 25 | M31: =L31 -> 25 | N31: =M31 -> 25 | O31: =N31 -> 25 | P31: =O31 -> 25 | Q31: =P31 -> 25
C32: Marketing cost $m | H32: =$K$25 -> 41 | I32: =$K$25 -> 41 | J32: =$K$25 -> 41 | K32: =$K$25 -> 41 | L32: =$K$25 -> 41 | M32: =$K$25 -> 41 | N32: =$K$25 -> 41 | O32: =$K$25 -> 41 | ... Q32: =$K$25 -> 41
B33: Sales and marketing costs $m | H33: =SUM(H30:H32) -> 109.33333 | I33: =SUM(I30:I32) -> 109.33333 | J33: =SUM(J30:J32) -> 109.33333 | K33: =SUM(K30:K32) -> 109.33333 | L33: =SUM(L30:L32) -> 109.33333 | M33: =SUM(M30:M32) -> 109.33333 | N33: =SUM(N30:N32) -> 109.33333 | O33: =SUM(O30:O32) -> 109.33333 | ... Q33: =SUM(Q30:Q32) -> 109.33333
B34: Sales and marketing costs $m including partner | H34: =H33 -> 109.33333 | I34: =I33 -> 109.33333 | J34: =J33 -> 109.33333 | K34: =K33 -> 109.33333 | L34: =L33 -> 109.33333 | M34: =M33 -> 109.33333 | N34: =N33 -> 109.33333 | O34: =O33 -> 109.33333 | ... Q34: =Q33 -> 109.33333
B35: Sales | H35: =Sales!J38 -> 71.165835 | I35: =Sales!K38 -> 390.65902 | J35: =Sales!L38 -> 676.77395 | K35: =Sales!M38 -> 1145.6168 | L35: =Sales!N38 -> 1475.4927 | M35: =Sales!O38 -> 1785.3692 | N35: =Sales!P38 -> 2127.5686 | O35: =Sales!Q38 -> 2404.2916 | ... Q35: =Sales!S38 -> 2901.8369
C36: % sales | H36: =H34/H35 -> 1.5363177 | I36: =I34/I35 -> 0.27986896 | J36: =J34/J35 -> 0.16155074 | K36: =K34/K35 -> 0.095436217 | L36: =L34/L35 -> 0.074099544 | M36: =M34/M35 -> 0.061238502 | N36: =N34/N35 -> 0.051388864 | O36: =O34/O35 -> 0.045474239 | ... Q36: =Q34/Q35 -> 0.037677284
B38: Non-US | I38: =Control!I15 -> 1 | J38: =I38 -> 1 | K38: =J38 -> 1 | L38: =K38 -> 1 | M38: =L38 -> 1 | N38: =Control!J15 -> 1 | O38: =N38 -> 1 | P38: =O38 -> 1 | Q38: =P38 -> 1
C39: Apportioned salesforce cost $m | I39: =$E$20*I38 -> 70 | J39: =$E$20*J38 -> 70 | K39: =$E$20*K38 -> 70 | L39: =$E$20*L38 -> 70 | M39: =$E$20*M38 -> 70 | N39: =$E$20*N38 -> 70 | O39: =$E$20*O38 -> 70 | P39: =$E$20*P38 -> 70 | Q39: =$E$20*Q38 -> 70
C40: Payer management | I40: =L11 -> 56.25 | J40: =I40 -> 56.25 | K40: =J40 -> 56.25 | L40: =K40 -> 56.25 | M40: =L40 -> 56.25 | N40: =M40 -> 56.25 | O40: =N40 -> 56.25 | P40: =O40 -> 56.25 | Q40: =P40 -> 56.25
C41: Marketing cost $m | I41: =$L$25 -> 52 | J41: =$L$25 -> 52 | K41: =$L$25 -> 52 | L41: =$L$25 -> 52 | M41: =$L$25 -> 52 | N41: =$L$25 -> 52 | O41: =$L$25 -> 52 | P41: =$L$25 -> 52 | Q41: =$L$25 -> 52
B42: Sales and marketing costs $m | H42: =SUM(H39:H41) -> 0 | I42: =SUM(I39:I41) -> 178.25 | J42: =SUM(J39:J41) -> 178.25 | K42: =SUM(K39:K41) -> 178.25 | L42: =SUM(L39:L41) -> 178.25 | M42: =SUM(M39:M41) -> 178.25 | N42: =SUM(N39:N41) -> 178.25 | O42: =SUM(O39:O41) -> 178.25 | ... Q42: =SUM(Q39:Q41) -> 178.25
B43: Sales | H43: =Sales!K134 -> 0 | I43: =Sales!K39 -> 53.555488 | J43: =Sales!L39 -> 363.58601 | K43: =Sales!M39 -> 713.74853 | L43: =Sales!N39 -> 1015.2856 | M43: =Sales!O39 -> 1280.1789 | N43: =Sales!P39 -> 1507.7218 | O43: =Sales!Q39 -> 1733.2251 | P43: =Sales!R39 -> 1950.5608 | Q43: =Sales!S39 -> 2070.6781
C44: % sales | I44: =I42/I43 -> 3.3283237 | J44: =J42/J43 -> 0.49025539 | K44: =K42/K43 -> 0.24973782 | L44: =L42/L43 -> 0.17556637 | M44: =M42/M43 -> 0.13923836 | N44: =N42/N43 -> 0.11822473 | O44: =O42/O43 -> 0.10284296 | P44: =P42/P43 -> 0.091383974 | Q44: =Q42/Q43 -> 0.086082913
...

Sheet Project
A1: PROJECT P&L AND CASH FLOW | E1: Assumptions in red | H1: Assumptions in yellow box from control panel
R3: Terminal
B4: Years from first launch | H4: 1 | I4: =H4+1 -> 2 | J4: =I4+1 -> 3 | K4: =J4+1 -> 4 | L4: =K4+1 -> 5 | M4: =L4+1 -> 6 | N4: =M4+1 -> 7 | O4: =N4+1 -> 8 | P4: =O4+1 -> 9 | Q4: =P4+1 -> 10 | R4: value
B5: Years from signature | E5: 0 | F5: 1 | G5: =F5+1 -> 2 | H5: =G5+1 -> 3 | I5: =H5+1 -> 4 | J5: =I5+1 -> 5 | K5: =J5+1 -> 6 | L5: =K5+1 -> 7 | M5: =L5+1 -> 8 | N5: =M5+1 -> 9 | ... Q5: =P5+1 -> 12 | R5: x sales
E6: =Control!M5 -> 2009 | F6: =E6+1 -> 2010 | G6: =F6+1 -> 2011 | H6: =G6+1 -> 2012 | I6: =H6+1 -> 2013 | J6: =I6+1 -> 2014 | K6: =J6+1 -> 2015 | L6: =K6+1 -> 2016 | M6: =L6+1 -> 2017 | ... Q6: =P6+1 -> 2021
R7: 3
A8: Total sales $m | D8: Sales | H8: =Sales!J40 -> 71.165835 | I8: =Sales!K40 -> 444.21451 | J8: =Sales!L40 -> 1040.36 | K8: =Sales!M40 -> 1859.3653 | L8: =Sales!N40 -> 2490.7782 | M8: =Sales!O40 -> 3065.548 | N8: =Sales!P40 -> 3635.2904 | O8: =Sales!Q40 -> 4137.5167 | ... Q8: =Sales!S40 -> 4972.515 | R8: =R7*Q8 -> 14917.545
A9: Costs of goods sold
B10: Cost of goods | D10: COG | E10: =COG!F59 -> 0 | F10: =COG!G59 -> 0 | G10: =COG!H59 -> 0 | H10: =COG!I59 -> 3.2903 | I10: =COG!J59 -> 24.939397 | J10: =COG!K59 -> 77.981651 | K10: =COG!L59 -> 98.456435 | L10: =COG!M59 -> 135.20064 | ... Q10: =COG!R59 -> 272.36064
B11: Distribution (% sales) | D11: 0.03 | E11: =$D$11*E8 -> 0 | F11: =$D$11*F8 -> 0 | G11: =$D$11*G8 -> 0 | H11: =$D$11*H8 -> 2.134975 | I11: =$D$11*I8 -> 13.326435 | J11: =$D$11*J8 -> 31.210799 | K11: =$D$11*K8 -> 55.78096 | L11: =$D$11*L8 -> 74.723347 | ... Q11: =$D$11*Q8 -> 149.17545
A12: Gross profit | E12: =E8-E10-E11 -> 0 | F12: =F8-F10-F11 -> 0 | G12: =G8-G10-G11 -> 0 | H12: =H8-H10-H11 -> 65.74056 | I12: =I8-I10-I11 -> 405.94868 | J12: =J8-J10-J11 -> 931.16751 | K12: =K8-K10-K11 -> 1705.1279 | L12: =L8-L10-L11 -> 2280.8543 | ... Q12: =Q8-Q10-Q11 -> 4550.9789 | R12: =R8 -> 14917.545
B13: Royalties payable (University) | D13: =Control!S13 -> 0.04 | E13: =$D$13*E8 -> 0 | F13: =$D$13*F8 -> 0 | G13: =$D$13*G8 -> 0 | H13: =$D$13*H8 -> 2.8466334 | I13: =$D$13*I8 -> 17.76858 | J13: =$D$13*J8 -> 41.614398 | K13: =$D$13*K8 -> 74.374613 | L13: =$D$13*L8 -> 99.63113 | ... Q13: =$D$13*Q8 -> 198.9006
B14: R&D | D14: R&D | E14: ='R&D'!I46 -> 18.924655 | F14: ='R&D'!J46 -> 56.540766 | G14: ='R&D'!K46 -> 86.296869 | H14: ='R&D'!L46 -> 110.10111 | I14: ='R&D'!M46 -> 117.7122 | J14: ='R&D'!N46 -> 140.43394 | K14: ='R&D'!O46 -> 135.41521 | L14: ='R&D'!P46 -> 84.721067 | ... Q14: ='R&D'!U46 -> 20
B15: Sales and Marketing | D15: S&M | E15: ='S&M'!E58 -> 0 | F15: ='S&M'!F58 -> 0 | G15: ='S&M'!G58 -> 0 | H15: ='S&M'!H58 -> 64.666667 | I15: ='S&M'!I58 -> 212.69583 | J15: ='S&M'!J58 -> 420.66667 | K15: ='S&M'!K58 -> 568.8625 | L15: ='S&M'!L58 -> 568.8625 | ... Q15: ='S&M'!Q58 -> 559.95
B16: General & Administration | D16: 0 | E16: =$D$16*E8 -> 0 | F16: =$D$16*F8 -> 0 | G16: =$D$16*G8 -> 0 | H16: =$D$16*H8 -> 0 | I16: =$D$16*I8 -> 0 | J16: =$D$16*J8 -> 0 | K16: =$D$16*K8 -> 0 | L16: =$D$16*L8 -> 0 | ... Q16: =$D$16*Q8 -> 0
A17: Total operating expenses | E17: =SUM(E13:E16) -> 18.924655 | F17: =SUM(F13:F16) -> 56.540766 | G17: =SUM(G13:G16) -> 86.296869 | H17: =SUM(H13:H16) -> 177.61441 | I17: =SUM(I13:I16) -> 348.17661 | J17: =SUM(J13:J16) -> 602.715 | K17: =SUM(K13:K16) -> 778.65232 | L17: =SUM(L13:L16) -> 753.2147 | ... R17: =SUM(R13:R16) -> 0
A18: Operating income / (loss) EBITDA | E18: =E12-E17 -> -18.924655 | F18: =F12-F17 -> -56.540766 | G18: =G12-G17 -> -86.296869 | H18: =H12-H17 -> -111.87385 | I18: =I12-I17 -> 57.772067 | J18: =J12-J17 -> 328.45251 | K18: =K12-K17 -> 926.47561 | L18: =L12-L17 -> 1527.6396 | ... R18: =R12-R17 -> 14917.545
B19: Depreciation & amortisation | D19: Ignored
B20: Tax | D20: Ignored
A21: Post tax profit | E21: =E18 -> -18.924655 | F21: =F18 -> -56.540766 | G21: =G18 -> -86.296869 | H21: =H18 -> -111.87385 | I21: =I18 -> 57.772067 | J21: =J18 -> 328.45251 | K21: =K18 -> 926.47561 | L21: =L18 -> 1527.6396 | ... R21: =R18 -> 14917.545
B22: Depreciation & amortisation
B23: Working capital movement
B24: Capital expenditure on manufacture
A25: Cash flow | E25: =E21+SUM(E22:E24) -> -18.924655 | F25: =F21+SUM(F22:F24) -> -56.540766 | G25: =G21+SUM(G22:G24) -> -86.296869 | H25: =H21+SUM(H22:H24) -> -111.87385 | I25: =I21+SUM(I22:I24) -> 57.772067 | J25: =J21+SUM(J22:J24) -> 328.45251 | K25: =K21+SUM(K22:K24) -> 926.47561 | L25: =L21+SUM(L22:L24) -> 1527.6396 | ... Q25: =Q21+SUM(Q22:Q24) -> 3772.1283 | R25: =R21+R22+R23+R24 -> 14917.545
A27: Payback | C27: Cumulative undiscounted cash flow | E27: =E25 -> -18.924655 | F27: =F25+E27 -> -75.465421 | G27: =G25+F27 -> -161.76229 | H27: =H25+G27 -> -273.63614 | I27: =I25+H27 -> -215.86407 | J27: =J25+I27 -> 112.58844 | K27: =K25+J27 -> 1039.0641 | L27: =L25+K27 -> 2566.7036 | M27: =M25+L27 -> 4635.2298 | ... Q27: =Q25+P27 -> 17523.272 | R27: =R25 -> 14917.545
D28: Years from signature | E28: =MATCH(0,$F$27:$Q$27,1) -> 4
A30: NPV of project excl sunk costs | D30: Cash flow | E30: =E25 -> -18.924655 | F30: =F25 -> -56.540766 | G30: =G25 -> -86.296869 | H30: =H25 -> -111.87385 | I30: =I25 -> 57.772067 | J30: =J25 -> 328.45251 | K30: =K25 -> 926.47561 | L30: =L25 -> 1527.6396 | ... R30: =R25 -> 14917.545
C31: Discount factor | D31: =Control!G45 -> 0.12 | E31: 1 | F31: =E31/(1+$D$31) -> 0.89285714 | G31: =F31/(1+$D$31) -> 0.79719388 | H31: =G31/(1+$D$31) -> 0.71178025 | I31: =H31/(1+$D$31) -> 0.63551808 | J31: =I31/(1+$D$31) -> 0.56742686 | K31: =J31/(1+$D$31) -> 0.50663112 | L31: =K31/(1+$D$31) -> 0.45234922 | M31: =L31/(1+$D$31) -> 0.40388323 | ... R31: =Q31/(1+$D$31) -> 0.22917419
C32: Discounted cash | E32: =E30*E31 -> -18.924655 | F32: =F30*F31 -> -50.482827 | G32: =G30*G31 -> -68.795336 | H32: =H30*H31 -> -79.629593 | I32: =I30*I31 -> 36.715193 | J32: =J30*J31 -> 186.37277 | K32: =K30*K31 -> 469.38138 | L32: =L30*L31 -> 691.02655 | ... R32: =R30*R31 -> 3418.7163
C33: Sum discounted cash | D33: $m | E33: =SUM(E32:R32) -> 9302.5829 | F33: to 2021 incl terminal value | J33: =SUM(E32:Q32) -> 5883.8666 | K33: to 2020 excl TV | P33: Terminal value | Q33: =E33-J33 -> 3418.7163
C34: Excel formula calc | D34: $m | E34: =NPV(D31,F30:R30)+E30 -> 9302.5829 | F34: to 2021 incl terminal value | J34: =NPV(D31,F30:Q30)+E30 -> 5883.8666 | K34: to 2020 excl TV | P34: Terminal value % of total | Q34: =Q33/E33 -> 0.36750184
C36: Internal rate of return | E36: =IRR(E30:R30) -> 0.89626858
A38: NPV of project including sunk costs
B39: Cash Flow incl sunk costs | E39: =-'Lor Financials'!D44 -> -17.194 | F39: =F25 -> -56.540766 | G39: =G25 -> -86.296869 | H39: =H25 -> -111.87385 | I39: =I25 -> 57.772067 | J39: =J25 -> 328.45251 | K39: =K25 -> 926.47561 | L39: =L25 -> 1527.6396 | M39: =M25 -> 2068.5262 | ... R39: =R25 -> 14917.545
B40: NPV | D40: =D31 -> 0.12 | E40: =NPV(D40,F39:R39)+E39 -> 9304.3135
B41: IRR | E41: =IRR(E39:R39) -> 0.90264674
A44: Working capital calculation | F44: =F6 -> 2010 | G44: =G6 -> 2011 | H44: =H6 -> 2012 | I44: =I6 -> 2013 | J44: =J6 -> 2014 | K44: =K6 -> 2015 | L44: =L6 -> 2016 | M44: =M6 -> 2017 | ... Q44: =Q6 -> 2021
B45: Receivables/debtors | D45: days sales outstanding | E45: 30 | F45: =F8/365*$E$45 -> 0 | G45: =G8/365*$E$45 -> 0 | H45: =H8/365*$E$45 -> 5.8492467 | I45: =I8/365*$E$45 -> 36.510782 | J45: =J8/365*$E$45 -> 85.509038 | K45: =K8/365*$E$45 -> 152.82455 | L45: =L8/365*$E$45 -> 204.7215 | M45: =M8/365*$E$45 -> 251.96285 | ... Q45: =Q8/365*$E$45 -> 408.69986
B46: Inventory/stock | D46: months of cost of goods | E46: 3 | F46: =F10/12*$E$46 -> 0 | G46: =G10/12*$E$46 -> 0 | H46: =H10/12*$E$46 -> 0.82257499 | I46: =I10/12*$E$46 -> 6.2348493 | J46: =J10/12*$E$46 -> 19.495413 | K46: =K10/12*$E$46 -> 24.614109 | L46: =L10/12*$E$46 -> 33.80016 | M46: =M10/12*$E$46 -> 42.02796 | ... Q46: =Q10/12*$E$46 -> 68.09016
B47: Payables/creditors | D47: days credt taken | E47: 30 | F47: =-F17/365*$E$47 -> -4.6471862 | G47: =-G17/365*$E$47 -> -7.0928934 | H47: =-H17/365*$E$47 -> -14.598444 | I47: =-I17/365*$E$47 -> -28.617256 | J47: =-J17/365*$E$47 -> -49.53822 | K47: =-K17/365*$E$47 -> -63.998821 | L47: =-L17/365*$E$47 -> -61.908057 | M47: =-M17/365*$E$47 -> -60.570707 | ... Q47: =-Q17/365*$E$47 -> -64.015118
...

Sheet Lee & Lor
A1: LICENSEE AND LICENSOR PROJECT VALUATIONS | F1: 1 | G1: =F1+1 -> 2 | H1: =G1+1 -> 3 | I1: =H1+1 -> 4 | J1: =I1+1 -> 5 | K1: =J1+1 -> 6 | L1: =K1+1 -> 7 | M1: =L1+1 -> 8 | N1: =M1+1 -> 9 | ... Q1: =P1+1 -> 12 | R1: Terminal
D2: =Control!Y2 -> 2008 | R2: value
A3: LICENSEE VALUATION | D3: $m | E3: =D2+1 -> 2009 | F3: =E3+1 -> 2010 | G3: =F3+1 -> 2011 | H3: =G3+1 -> 2012 | I3: =H3+1 -> 2013 | J3: =I3+1 -> 2014 | K3: =J3+1 -> 2015 | L3: =K3+1 -> 2016 | M3: =L3+1 -> 2017 | ... Q3: =P3+1 -> 2021 | R3: =Project!R7 -> 3
B4: Total Sales | H4: =H6+H13 -> 71.165835 | I4: =I6+I13 -> 444.21451 | J4: =J6+J13 -> 1040.36 | K4: =K6+K13 -> 1859.3653 | L4: =L6+L13 -> 2490.7782 | M4: =M6+M13 -> 3065.548 | N4: =N6+N13 -> 3635.2904 | O4: =O6+O13 -> 4137.5167 | ... Q4: =Q6+Q13 -> 4972.515 | R4: =R3*Q4 -> 14917.545
C5: US
B6: Sales | H6: =Sales!J38 -> 71.165835 | I6: =Sales!K38 -> 390.65902 | J6: =Sales!L38 -> 676.77395 | K6: =Sales!M38 -> 1145.6168 | L6: =Sales!N38 -> 1475.4927 | M6: =Sales!O38 -> 1785.3692 | N6: =Sales!P38 -> 2127.5686 | O6: =Sales!Q38 -> 2404.2916 | ... Q6: =Sales!S38 -> 2901.8369
C7: Cost of goods sold | E7: =COG!F60 -> 0 | F7: =COG!G60 -> 0 | G7: =COG!H60 -> 0 | H7: =COG!I60 -> 3.2903 | I7: =COG!J60 -> 18.061832 | J7: =COG!K60 -> 31.290145 | K7: =COG!L60 -> 36.05797 | L7: =COG!M60 -> 46.440721 | ... Q7: =COG!R60 -> 91.334511
C8: Distribution | D8: 0.03 | E8: =$D$8*E6 -> 0 | F8: =$D$8*F6 -> 0 | G8: =$D$8*G6 -> 0 | H8: =$D$8*H6 -> 2.134975 | I8: =$D$8*I6 -> 11.719771 | J8: =$D$8*J6 -> 20.303218 | K8: =$D$8*K6 -> 34.368504 | L8: =$D$8*L6 -> 44.26478 | ... Q8: =$D$8*Q6 -> 87.055108
B9: Gross profit | E9: =E6-SUM(E7:E8) -> 0 | F9: =F6-SUM(F7:F8) -> 0 | G9: =G6-SUM(G7:G8) -> 0 | H9: =H6-SUM(H7:H8) -> 65.74056 | I9: =I6-SUM(I7:I8) -> 360.87742 | J9: =J6-SUM(J7:J8) -> 625.18059 | K9: =K6-SUM(K7:K8) -> 1075.1903 | L9: =L6-SUM(L7:L8) -> 1384.7872 | ... Q9: =Q6-SUM(Q7:Q8) -> 2723.4473
C10: Sales and Marketing | E10: ='S&M'!E55 -> 0 | F10: ='S&M'!F55 -> 0 | G10: ='S&M'!G55 -> 0 | H10: ='S&M'!H55 -> 54.666667 | I10: ='S&M'!I55 -> 142.13333 | J10: ='S&M'!J55 -> 235.06667 | K10: ='S&M'!K55 -> 262.4 | L10: ='S&M'!L55 -> 262.4 | ... Q10: ='S&M'!Q55 -> 262.4
B11: US profit contribution | E11: =E9-E10 -> 0 | F11: =F9-F10 -> 0 | G11: =G9-G10 -> 0 | H11: =H9-H10 -> 11.073893 | I11: =I9-I10 -> 218.74409 | J11: =J9-J10 -> 390.11392 | K11: =K9-K10 -> 812.79033 | L11: =L9-L10 -> 1122.3872 | ... Q11: =Q9-Q10 -> 2461.0473
C12: NON-US
B13: Sales | H13: =Sales!J39 -> 0 | I13: =Sales!K39 -> 53.555488 | J13: =Sales!L39 -> 363.58601 | K13: =Sales!M39 -> 713.74853 | L13: =Sales!N39 -> 1015.2856 | M13: =Sales!O39 -> 1280.1789 | N13: =Sales!P39 -> 1507.7218 | O13: =Sales!Q39 -> 1733.2251 | ... Q13: =Sales!S39 -> 2070.6781
C14: Cost of goods sold | H14: =COG!I61 -> 0 | I14: =COG!J61 -> 6.8775649 | J14: =COG!K61 -> 46.691506 | K14: =COG!L61 -> 62.398465 | L14: =COG!M61 -> 88.759919 | M14: =COG!N61 -> 111.91784 | N14: =COG!O61 -> 131.81046 | O14: =COG!P61 -> 151.52477 | ... Q14: =COG!R61 -> 181.02613
C15: Distribution | D15: 0.03 | E15: =$D$8*E13 -> 0 | F15: =$D$8*F13 -> 0 | G15: =$D$8*G13 -> 0 | H15: =$D$8*H13 -> 0 | I15: =$D$8*I13 -> 1.6066646 | J15: =$D$8*J13 -> 10.90758 | K15: =$D$8*K13 -> 21.412456 | L15: =$D$8*L13 -> 30.458567 | ... Q15: =$D$8*Q13 -> 62.120342
B16: Gross profit | E16: =E13-SUM(E14:E15) -> 0 | F16: =F13-SUM(F14:F15) -> 0 | G16: =G13-SUM(G14:G15) -> 0 | H16: =H13-SUM(H14:H15) -> 0 | I16: =I13-SUM(I14:I15) -> 45.071258 | J16: =J13-SUM(J14:J15) -> 305.98692 | K16: =K13-SUM(K14:K15) -> 629.93761 | L16: =L13-SUM(L14:L15) -> 896.0671 | ... Q16: =Q13-SUM(Q14:Q15) -> 1827.5316
C17: Sales and Marketing | E17: ='S&M'!E57 -> 0 | F17: ='S&M'!F57 -> 0 | G17: ='S&M'!G57 -> 0 | H17: ='S&M'!H57 -> 0 | I17: ='S&M'!I57 -> 44.5625 | J17: ='S&M'!J57 -> 142.6 | K17: ='S&M'!K57 -> 258.4625 | L17: ='S&M'!L57 -> 258.4625 | ... Q17: ='S&M'!Q57 -> 249.55
B18: Non US profit contribution | E18: =E16-E17 -> 0 | F18: =F16-F17 -> 0 | G18: =G16-G17 -> 0 | H18: =H16-H17 -> 0 | I18: =I16-I17 -> 0.50875825 | J18: =J16-J17 -> 163.38692 | K18: =K16-K17 -> 371.47511 | L18: =L16-L17 -> 637.6046 | ... Q18: =Q16-Q17 -> 1577.9816
C19: R&D | E19: ='R&D'!I37 -> 16.474655 | F19: ='R&D'!J37 -> 53.840766 | G19: ='R&D'!K37 -> 82.946869 | H19: ='R&D'!L37 -> 105.06947 | I19: ='R&D'!M37 -> 110.82753 | J19: ='R&D'!N37 -> 132.69908 | K19: ='R&D'!O37 -> 128.50458 | L19: ='R&D'!P37 -> 83.266347 | ... Q19: ='R&D'!U37 -> 20
C20: G&A | D20: 0 | H20: =$D$20*(H13+H6) -> 0 | I20: =$D$20*(I13+I6) -> 0 | J20: =$D$20*(J13+J6) -> 0 | K20: =$D$20*(K13+K6) -> 0 | L20: =$D$20*(L13+L6) -> 0 | M20: =$D$20*(M13+M6) -> 0 | N20: =$D$20*(N13+N6) -> 0 | O20: =$D$20*(O13+O6) -> 0 | ... Q20: =$D$20*(Q13+Q6) -> 0
B21: Operating profit pre deal terms | E21: =E11+E18-E19-E20 -> -16.474655 | F21: =F11+F18-F19-F20 -> -53.840766 | G21: =G11+G18-G19-G20 -> -82.946869 | H21: =H11+H18-H19-H20 -> -93.995572 | I21: =I11+I18-I19-I20 -> 108.42532 | J21: =J11+J18-J19-J20 -> 420.80177 | K21: =K11+K18-K19-K20 -> 1055.7609 | L21: =L11+L18-L19-L20 -> 1676.7254 | ... Q21: =Q11+Q18-Q19-Q20 -> 4019.0289 | R21: =R4 -> 14917.545
